Workbook

Sheet REGLES POUR RECO DU CONCEPT
E2: SIMPLY | K2: LIBERTY | Q2: CONNECTED
B4: REGLE #1 | D4: Nb. de chambres | E4: Entre 0 et 49 chambres | K4: + de 50 chambres | Q4: + de 50 chambres
F6: Nb. hôtels | L6: Nb. hôtels | R6: Nb. hôtels
E7: IBB | F7: ='NB CH 2'!C3 -> 45 | K7: IBB | L7: ='NB CH 2'!C2-'NB CH 2'!C3 -> 297 | Q7: IBB | R7: =L7 -> 297
E8: IBS | F8: ='NB CH 2'!C11 -> 60 | K8: IBS | L8: ='NB CH 2'!C10-'NB CH 2'!C11 -> 207 | Q8: IBS | R8: =L8 -> 207
E9: IBIS | F9: ='NB CH 2'!C19 -> 45 | K9: IBIS | L9: ='NB CH 2'!C18-'NB CH 2'!C19 -> 317 | Q9: IBIS | R9: =L9 -> 317
E10: NOV | F10: 0 | K10: NOV | L10: ='NB CH 2'!C26-'NB CH 2'!C27 -> 117 | Q10: NOV | R10: =L10 -> 117
E11: MER | F11: ='NB CH 2'!C35 -> 28 | K11: MER | L11: ='NB CH 2'!C34-'NB CH 2'!C35 -> 227 | Q11: MER | R11: =L11 -> 227
E12: TOTAL | F12: =SUM(F7:F11) -> 178 | G12: =F12/H12 -> 0.13253909 | H12: 1343 | K12: TOTAL | L12: =SUM(L7:L11) -> 1165 | M12: =L12/N12 -> 0.86746091 | N12: 1343 | Q12: TOTAL | R12: =SUM(R7:R11) -> 1165 | S12: =R12/T12 -> 0.86746091 | T12: 1343
B15: REGLE #2 | D15: Min. 1 des 5 catégories :
D16: Cosmetics et/ou Kids items et/ou Ready-to-wear et/ou Accessories et/ou Souvenirs | K16: YES | Q16: NO
L18: Nb. hôtels | R18: Nb. hôtels
K19: IBB | L19: 0 | Q19: IBB | R19: =L7 -> 297
G20: Le choix doit être possible pour les hôtels NOV et MER ↔ | K20: IBS | L20: 0 | Q20: IBS | R20: =L8 -> 207
K21: IBIS | L21: 0 | Q21: IBIS | R21: =L9 -> 317
E22: NOV | F22: =L22 -> 117 | K22: NOV | L22: =L10 -> 117 | Q22: NOV | R22: 0
E23: MER | F23: =L23 -> 227 | K23: MER | L23: =L11 -> 227 | Q23: MER | R23: 0
E24: TOTAL | F24: =SUM(F19:F23) -> 344 | G24: =F24/H24 -> 0.25614296 | H24: 1343 | K24: TOTAL | L24: =SUM(L19:L23) -> 344 | M24: =L24/N24 -> 0.25614296 | N24: 1343 | Q24: TOTAL | R24: =SUM(R19:R23) -> 821 | S24: =R24/T24 -> 0.61131794 | T24: 1343
B27: REGLE #3 | D27: Nb. de mètres linéaires :
D28: Si l'hôtel souhaite + de 4 mètres linéaires alors > LIBERTY STORE | K28: > 4 METRES LINEAIRES | Q28: < ou = 4 METRES LINEAIRES
L30: Nb. hôtels | R30: Nb. hôtels
K31: IBB | L31: =$R$19*M31 -> 29.7 | M31: 0.1 | Q31: IBB | R31: =$R$19*S31 -> 267.3 | S31: =100%-M31 -> 0.9
K32: IBS | L32: =$R$20*M32 -> 62.1 | M32: 0.3 | Q32: IBS | R32: =$R$20*S32 -> 144.9 | S32: =100%-M32 -> 0.7
K33: IBIS | L33: =$R$21*M33 -> 63.4 | M33: 0.2 | Q33: IBIS | R33: =$R$21*S33 -> 253.6 | S33: =100%-M33 -> 0.8
K34: TOTAL | L34: =SUM(L31:L33) -> 155.2 | M34: =L34/N34 -> 0.11556217 | N34: 1343 | Q34: TOTAL | R34: =SUM(R31:R33) -> 665.8 | S34: =R34/T34 -> 0.49575577 | T34: 1343
B36: Pour les hôtels répondant aux critères ci-après : | G36: - Plus de 50 chambres - Aucune des 5 catégories de produits sélectionnées/cochées - Entre 2 et 4 mètres linéaires accordés à leur future boutique (2 mètres étant le minimum dans ROD)
Q38: METRES LINEAIRES = ou < 4
B42: REGLE #4 | D42: L'hôtel est-il déjà en possession d'une vitrine réfrigérée ? | K42: YES | Q42: NO
L44: Nb. hôtels | R44: Nb. hôtels
K45: IBB | L45: =$R$31*M45 -> 106.92 | M45: 0.4 | Q45: IBB | R45: =$R$31*S45 -> 160.38 | S45: =100%-M45 -> 0.6
K46: IBS | L46: =$R$32*M46 -> 72.45 | M46: 0.5 | Q46: IBS | R46: =$R$32*S46 -> 72.45 | S46: =100%-M46 -> 0.5
K47: IBIS | L47: =$R$33*M47 -> 152.16 | M47: 0.6 | Q47: IBIS | R47: =$R$33*S47 -> 101.44 | S47: =100%-M47 -> 0.4
K48: TOTAL | L48: =SUM(L45:L47) -> 331.53 | M48: =L48/N48 -> 0.24685778 | N48: 1343 | Q48: TOTAL | R48: =SUM(R45:R47) -> 334.27 | S48: =R48/T48 -> 0.24889799 | T48: 1343
B52: REGLE #5 | D52: Dernier tri en fonction du TO moyen (YTD) | K52: TO < à 70% | Q52: TO = ou > à 70%
L54: Nb. hôtels | R54: Nb. hôtels
K55: IBB | L55: =$R$45*M55 -> 64.152 | M55: 0.4 | Q55: IBB | R55: =$R$45*S55 -> 96.228 | S55: =100%-M55 -> 0.6
K56: IBS | L56: =$R$46*M56 -> 21.735 | M56: 0.3 | Q56: IBS | R56: =$R$46*S56 -> 50.715 | S56: =100%-M56 -> 0.7
K57: IBIS | L57: =$R$47*M57 -> 20.288 | M57: 0.2 | Q57: IBIS | R57: =$R$47*S57 -> 81.152 | S57: =100%-M57 -> 0.8
K58: TOTAL | L58: =SUM(L55:L57) -> 106.175 | M58: =L58/N58 -> 0.079058079 | N58: 1343 | Q58: TOTAL | R58: =SUM(R55:R57) -> 228.095 | S58: =R58/T58 -> 0.16983991 | T58: 1343
B60: NB. HOTELS TOTAUX | E60: =F12 -> 178 | K60: =SUM(L24,L34,L48,L58) -> 936.905 | Q60: =R58 -> 228.095
...

Sheet NB CH 1
A2: Étiquettes de lignes | B2: Nombre de CODE H
A3: IBIS BUDGET | B3: 342
A4: Plus de 300 ch. | B4: 1
A5: Entre 50 et 99 ch. | B5: 252
A6: Entre 100 et 149 ch. | B6: 31
A7: Entre 150 et 199 ch. | B7: 7
A8: Entre 0 et 49 ch. | B8: 45
A9: Entre 250 et 299 ch. | B9: 3
A10: Entre 200 et 249 ch. | B10: 3
A11: IBIS STYLES | B11: 267
A12: Plus de 300 ch. | B12: 3
A13: Entre 50 et 99 ch. | B13: 174
A14: Entre 100 et 149 ch. | B14: 26
... A40: Total général | B40: 1343

Sheet NB CH 2
B2: IBIS BUDGET | C2: 342 | D2: =C2/$C$2 -> 1
B3: Entre 0 et 49 ch. | C3: 45 | D3: =C3/$C$2 -> 0.13157895
B4: Entre 50 et 99 ch. | C4: 252 | D4: =C4/$C$2 -> 0.73684211
B5: Entre 100 et 149 ch. | C5: 31 | D5: =C5/$C$2 -> 0.090643275
B6: Entre 150 et 199 ch. | C6: 7 | D6: =C6/$C$2 -> 0.020467836
B7: Entre 200 et 249 ch. | C7: 3 | D7: =C7/$C$2 -> 0.0087719298
B8: Entre 250 et 299 ch. | C8: 3 | D8: =C8/$C$2 -> 0.0087719298
B9: Plus de 300 ch. | C9: 1 | D9: =C9/$C$2 -> 0.0029239766
B10: IBIS STYLES | C10: 267 | D10: =C10/$C$10 -> 1
B11: Entre 0 et 49 ch. | C11: 60 | D11: =C11/$C$10 -> 0.2247191
B12: Entre 50 et 99 ch. | C12: 174 | D12: =C12/$C$10 -> 0.65168539
B13: Entre 100 et 149 ch. | C13: 26 | D13: =C13/$C$10 -> 0.097378277
B14: Entre 150 et 199 ch. | C14: 3 | D14: =C14/$C$10 -> 0.011235955
B15: Entre 200 et 249 ch. | C15: 1 | D15: =C15/$C$10 -> 0.0037453184
B16: Entre 250 et 299 ch. | C16: 0 | D16: =C16/$C$10 -> 0
B17: Plus de 300 ch. | C17: 3 | D17: =C17/$C$10 -> 0.011235955
B18: IBIS | C18: 362 | D18: =C18/$C$18 -> 1
B19: Entre 0 et 49 ch. | C19: 45 | D19: =C19/$C$18 -> 0.12430939
B20: Entre 50 et 99 ch. | C20: 247 | D20: =C20/$C$18 -> 0.68232044
B21: Entre 100 et 149 ch. | C21: 45 | D21: =C21/$C$18 -> 0.12430939
B22: Entre 150 et 199 ch. | C22: 11 | D22: =C22/$C$18 -> 0.03038674
B23: Entre 200 et 249 ch. | C23: 3 | D23: =C23/$C$18 -> 0.0082872928
B24: Entre 250 et 299 ch. | C24: 4 | D24: =C24/$C$18 -> 0.011049724
B25: Plus de 300 ch. | C25: 7 | D25: =C25/$C$18 -> 0.019337017
B26: NOVOTEL | C26: 117 | D26: =C26/$C$26 -> 1
B27: Entre 0 et 49 ch. | C27: 0 | D27: =C27/$C$26 -> 0
B28: Entre 50 et 99 ch. | C28: 37 | D28: =C28/$C$26 -> 0.31623932
B29: Entre 100 et 149 ch. | C29: 57 | D29: =C29/$C$26 -> 0.48717949
B30: Entre 150 et 199 ch. | C30: 15 | D30: =C30/$C$26 -> 0.12820513
B31: Entre 200 et 249 ch. | C31: 2 | D31: =C31/$C$26 -> 0.017094017
B32: Entre 250 et 299 ch. | C32: 4 | D32: =C32/$C$26 -> 0.034188034
B33: Plus de 300 ch. | C33: 2 | D33: =C33/$C$26 -> 0.017094017
B34: MERCURE | C34: 255 | D34: =C34/$C$34 -> 1
B35: Entre 0 et 49 ch. | C35: 28 | D35: =C35/$C$34 -> 0.10980392
B36: Entre 50 et 99 ch. | C36: 155 | D36: =C36/$C$34 -> 0.60784314
B37: Entre 100 et 149 ch. | C37: 45 | D37: =C37/$C$34 -> 0.17647059
B38: Entre 150 et 199 ch. | C38: 15 | D38: =C38/$C$34 -> 0.058823529
B39: Entre 200 et 249 ch. | C39: 5 | D39: =C39/$C$34 -> 0.019607843
B40: Entre 250 et 299 ch. | C40: 0 | D40: =C40/$C$34 -> 0
B41: Plus de 300 ch. | C41: 7 | D41: =C41/$C$34 -> 0.02745098
...

Sheet RESTO 1
A2: Nombre de CODE H | B2: Étiquettes de colonnes
A3: Étiquettes de lignes | B3: 0 | C3: 1 | D3: 2 | E3: 3 | F3: Total général
A4: IBIS | B4: 181 | C4: 176 | D4: 4 | E4: 1 | F4: 362
A5: IBIS BUDGET | B5: 314 | C5: 28 | F5: 342
A6: IBIS STYLES | B6: 181 | C6: 81 | D6: 4 | E6: 1 | F6: 267
A7: MERCURE | B7: 106 | C7: 140 | D7: 8 | E7: 1 | F7: 255
A8: NOVOTEL | B8: 5 | C8: 102 | D8: 7 | E8: 3 | F8: 117
A9: Total général | B9: 787 | C9: 527 | D9: 23 | E9: 6 | F9: 1343

Sheet RESTO 2
B2: NB. DE RESTAURANT(S) | C2: 0 | E2: 1 | G2: 2 | I2: 3 | L2: NB. HOTELS | M2: CHECK
B3: IBIS BUDGET | C3: 314 | D3: =C3/$L$3 -> 0.91812865 | E3: 28 | F3: =E3/$L$3 -> 0.081871345 | L3: 342 | M3: =SUM(D3,F3,H3,J3) -> 1
B4: IBIS STYLES | C4: 181 | D4: =C4/$L$4 -> 0.67790262 | E4: 81 | F4: =E4/$L$4 -> 0.30337079 | G4: 4 | H4: =G4/$L$4 -> 0.014981273 | I4: 1 | L4: 267 | M4: =SUM(D4,F4,H4,J4) -> 0.99625468
B5: IBIS | C5: 181 | D5: =C5/$L$5 -> 0.5 | E5: 176 | F5: =E5/$L$5 -> 0.48618785 | G5: 4 | H5: =G5/$L$5 -> 0.011049724 | I5: 1 | L5: 362 | M5: =SUM(D5,F5,H5,J5) -> 0.99723757
B6: NOVOTEL | C6: 5 | D6: =C6/$L$6 -> 0.042735043 | E6: 102 | F6: =E6/$L$6 -> 0.87179487 | G6: 7 | H6: =G6/$L$6 -> 0.05982906 | I6: 3 | J6: =I6/$L$6 -> 0.025641026 | L6: 117 | M6: =SUM(D6,F6,H6,J6) -> 1
B7: MERCURE | C7: 106 | D7: =C7/$L$7 -> 0.41568627 | E7: 140 | F7: =E7/$L$7 -> 0.54901961 | G7: 8 | H7: =G7/$L$7 -> 0.031372549 | I7: 1 | J7: =I7/$L$7 -> 0.0039215686 | L7: 255 | M7: =SUM(D7,F7,H7,J7) -> 1
B8: TOTAL | C8: 787 | D8: =C8/$L$8 -> 0.58600149 | E8: 527 | F8: =E8/$L$8 -> 0.39240506 | G8: 23 | H8: =G8/$L$8 -> 0.017125838 | I8: 6 | J8: =I8/$L$8 -> 0.0044676098 | L8: 1343 | M8: =SUM(D8,F8,H8,J8) -> 1

Sheet BAR 1
A2: Nombre de CODE H | B2: Étiquettes de colonnes
A3: Étiquettes de lignes | B3: 0 | C3: 1 | D3: 2 | E3: 3 | F3: Total général
A4: IBIS | B4: 15 | C4: 341 | D4: 6 | F4: 362
A5: IBIS BUDGET | B5: 319 | C5: 23 | F5: 342
A6: IBIS STYLES | B6: 48 | C6: 218 | D6: 1 | F6: 267
A7: MERCURE | B7: 27 | C7: 224 | D7: 3 | E7: 1 | F7: 255
A8: NOVOTEL | B8: 1 | C8: 107 | D8: 9 | F8: 117
A9: Total général | B9: 410 | C9: 913 | D9: 19 | E9: 1 | F9: 1343

Sheet BAR 2
B2: NB. DE BAR(S) | C2: 0 | E2: 1 | G2: 2 | I2: 3 | L2: NB. HOTELS | M2: CHECK
B3: IBIS BUDGET | C3: 319 | D3: =C3/$L$3 -> 0.93274854 | E3: 23 | F3: =E3/$L$3 -> 0.067251462 | L3: 342 | M3: =SUM(D3,F3,H3,J3) -> 1
B4: IBIS STYLES | C4: 48 | D4: =C4/$L$4 -> 0.17977528 | E4: 218 | F4: =E4/$L$4 -> 0.8164794 | G4: 1 | H4: =G4/$L$4 -> 0.0037453184 | L4: 267 | M4: =SUM(D4,F4,H4,J4) -> 1
B5: IBIS | C5: 15 | D5: =C5/$L$5 -> 0.041436464 | E5: 341 | F5: =E5/$L$5 -> 0.94198895 | G5: 6 | H5: =G5/$L$5 -> 0.016574586 | L5: 362 | M5: =SUM(D5,F5,H5,J5) -> 1
B6: NOVOTEL | C6: 1 | D6: =C6/$L$6 -> 0.0085470085 | E6: 107 | F6: =E6/$L$6 -> 0.91452991 | G6: 9 | H6: =G6/$L$6 -> 0.076923077 | L6: 117 | M6: =SUM(D6,F6,H6,J6) -> 1
B7: MERCURE | C7: 27 | D7: =C7/$L$7 -> 0.10588235 | E7: 224 | F7: =E7/$L$7 -> 0.87843137 | G7: 3 | H7: =G7/$L$7 -> 0.011764706 | I7: 1 | J7: =I7/$L$7 -> 0.0039215686 | L7: 255 | M7: =SUM(D7,F7,H7,J7) -> 1
B8: TOTAL | C8: 410 | D8: =C8/$L$8 -> 0.30528667 | E8: 913 | F8: =E8/$L$8 -> 0.6798213 | G8: 19 | H8: =G8/$L$8 -> 0.014147431 | I8: 1 | J8: =I8/$L$8 -> 0.00074460164 | L8: 1343 | M8: =SUM(D8,F8,H8,J8) -> 1

Sheet CRITERES POUR PANEL
B2: CRITERES POUR PANEL REPRESENTATIF (TESTS SIMULATEUR)
C4: NB. CH. | D4: NB. RESTO | E4: NB. BAR
B5: IBIS BUDGET | C5: Entre 50 et 99 ch. | D5: 0 | E5: 0
B6: IBIS STYLES | C6: Entre 50 et 99 ch. | D6: 0 | E6: 1
B7: IBIS | C7: Entre 50 et 99 ch. | D7: 0 et 1 | E7: 1
B8: NOVOTEL | C8: Entre 100 et 149 ch. | D8: 1 | E8: 1
B9: MERCURE | C9: Entre 50 et 99 ch. | D9: 1 | E9: 1

Sheet TESTS SIMPLY
B2: SIMPLY
B4: HB523 | C4: IBIS BUDGET LYON EST BEYNOST | I4: H6916 | J4: IBIS STYLES ORLEANS | P4: H5302 | Q4: IBIS TOUR MONTPARNASSE | W4: H1951 | X4: MERCURE CAVAILLON LUBERON
B6: NB. CH. | C6: 40 | E6: ML | G6: 2 | I6: NB. CH. | J6: 42 | L6: ML | N6: 3 | P6: NB. CH. | Q6: 45 | S6: ML | U6: 4 | W6: NB. CH. | X6: 47 | Z6: ML | AB6: 4
B7: NB. G / CH. | C7: 1.5 | E7: F&B | G7: 0.9 | I7: NB. G / CH. | J7: 1.5 | L7: F&B | N7: 0.7 | P7: NB. G / CH. | Q7: 1.5 | S7: F&B | U7: 0.8 | W7: NB. G / CH. | X7: 1.5 | Z7: F&B | AB7: 0.7
B8: TO (YTD) | C8: 0.7 | E8: N-F&B | G8: 0.1 | I8: TO (YTD) | J8: 0.7 | L8: N-F&B | N8: 0.3 | P8: TO (YTD) | Q8: 0.7 | S8: N-F&B | U8: 0.2 | W8: TO (YTD) | X8: 0.7 | Z8: N-F&B | AB8: 0.3
B11: Drinks w-out A | C11: X | E11: SOS | G11: X | I11: Drinks w-out A | J11: X | L11: SOS | N11: X | P11: Drinks w-out A | Q11: X | S11: SOS | U11: X | W11: Drinks w-out A | X11: X | Z11: SOS | AB11: X
B12: Drinks w A | C12: X | E12: Hygiene | I12: Drinks w A | J12: X | L12: Hygiene | N12: X | P12: Drinks w A | Q12: X | S12: Hygiene | U12: X | W12: Drinks w A | X12: X | Z12: Hygiene | AB12: X
B13: Sugary (dry) | C13: X | E13: Cosmetics | I13: Sugary (dry) | J13: X | L13: Cosmetics | P13: Sugary (dry) | Q13: X | S13: Cosmetics | W13: Sugary (dry) | X13: X | Z13: Cosmetics | AB13: X
B14: Sugary (fresh) | C14: X | E14: Kids items | I14: Sugary (fresh) | J14: X | L14: Kids items | P14: Sugary (fresh) | Q14: X | S14: Kids items | W14: Sugary (fresh) | X14: X | Z14: Kids items
B15: Salty (dry) | C15: X | E15: Ready-to-wear | I15: Salty (dry) | J15: X | L15: Ready-to-wear | P15: Salty (dry) | Q15: X | S15: Ready-to-wear | W15: Salty (dry) | X15: X | Z15: Ready-to-wear
B16: Salty (fresh) | C16: X | E16: Accessories | I16: Salty (fresh) | J16: X | L16: Accessories | N16: X | P16: Salty (fresh) | Q16: X | S16: Accessories | W16: Salty (fresh) | X16: X | Z16: Accessories
B17: Gourmet | E17: Souvenirs | I17: Gourmet | L17: Souvenirs | N17: X | P17: Gourmet | S17: Souvenirs | W17: Gourmet | X17: X | Z17: Souvenirs | AB17: X
B20: SCANNER | C20: 1 | I20: SCANNER | J20: 1 | P20: SCANNER | Q20: 1 | W20: SCANNER | X20: 1
B21: VITRINE | C21: 1 | I21: VITRINE | J21: 1 | P21: VITRINE | Q21: 1 | W21: VITRINE | X21: 1
B22: AGENCEMENT | C22: Classic | E22: + Testé en "Premium" | I22: AGENCEMENT | J22: Classic | L22: + Testé en "Premium" | P22: AGENCEMENT | Q22: Classic | S22: + Testé en "Premium" | W22: AGENCEMENT | X22: Premium | Z22: + Testé en "Classic"
B25: REVENUS | C25: THOMAS | E25: ROD | I25: REVENUS | J25: THOMAS | L25: ROD | P25: REVENUS | Q25: THOMAS | S25: ROD | W25: REVENUS | X25: THOMAS | Z25: ROD
B27: F&B | C27: 796 | E27: 794 | F27: /mois | I27: F&B | J27: 507 | L27: 506 | M27: /mois | P27: F&B | Q27: 803 | S27: 802 | T27: /mois | W27: F&B | X27: 636 | Z27: 635 | AA27: /mois
B28: NON-F&B | C28: -227 | E28: -225 | F28: /mois | I28: NON-F&B | J28: -131 | L28: -130 | M28: /mois | P28: NON-F&B | Q28: -127 | S28: -126 | T28: /mois | W28: NON-F&B | X28: -95 | Z28: -95 | AA28: /mois
B29: TOTAL | C29: =SUM(C27:C28) -> 569 | E29: 568 | F29: /mois | I29: TOTAL | J29: =SUM(J27:J28) -> 376 | L29: 376 | M29: /mois | P29: TOTAL | Q29: =SUM(Q27:Q28) -> 676 | S29: 676 | T29: /mois | W29: TOTAL | X29: =SUM(X27:X28) -> 541 | Z29: 540 | AA29: /mois
B32: MARGE NETTE | C32: 292 | E32: 291 | F32: /mois | I32: MARGE NETTE | J32: 132 | L32: 132 | M32: /mois | P32: MARGE NETTE | Q32: 304 | S32: 303 | T32: /mois | W32: MARGE NETTE | X32: 201 | Z32: 203 | AA32: /mois
B33: AMORTISSEMENT | C33: 28 | E33: 26 | F33: mois | I33: AMORTISSEMENT | J33: 69 | L33: 63 | M33: mois | P33: AMORTISSEMENT | Q33: 34 | S33: 30 | T33: mois | W33: AMORTISSEMENT | X33: 55 | Z33: 47 | AA33: mois

Sheet TESTS LIBERTY
B2: LIBERTY
B4: H6675 | C4: IBIS BUDGET BORDEAUX SUD | I4: HB7P3 | J4: IBIS STYLES RENNES CESSON | P4: H0538 | Q4: IBIS ANNECY CTRE VIEILLE VILLE | W4: H0412 | X4: NOVOTEL NARBONNE SUD | AD4: H1625 | AE4: MERCURE LYON CHARPENNES
B6: NB. CH. | C6: 76 | E6: ML | G6: 5 | I6: NB. CH. | J6: 64 | L6: ML | N6: 5 | P6: NB. CH. | Q6: 85 | S6: ML | U6: 5 | W6: NB. CH. | X6: 93 | Z6: ML | AB6: 6 | AD6: NB. CH. | AE6: 98 | AG6: ML | AI6: 6
B7: NB. G / CH. | C7: 1.5 | E7: F&B | G7: 0.9 | I7: NB. G / CH. | J7: 1.5 | L7: F&B | N7: 0.7 | P7: NB. G / CH. | Q7: 1.5 | S7: F&B | U7: 0.8 | W7: NB. G / CH. | X7: 1.5 | Z7: F&B | AB7: 0.7 | AD7: NB. G / CH. | AE7: 1.5 | AG7: F&B | AI7: 0.7
B8: TO (YTD) | C8: 0.7 | E8: N-F&B | G8: 0.1 | I8: TO (YTD) | J8: 0.7 | L8: N-F&B | N8: 0.3 | P8: TO (YTD) | Q8: 0.7 | S8: N-F&B | U8: 0.2 | W8: TO (YTD) | X8: 0.7 | Z8: N-F&B | AB8: 0.3 | AD8: TO (YTD) | AE8: 0.7 | AG8: N-F&B | AI8: 0.3
B11: Drinks w-out A | C11: X | E11: SOS | G11: X | I11: Drinks w-out A | J11: X | L11: SOS | N11: X | P11: Drinks w-out A | Q11: X | S11: SOS | U11: X | W11: Drinks w-out A | X11: X | Z11: SOS | AB11: X | AD11: Drinks w-out A | AE11: X | AG11: SOS | AI11: X
B12: Drinks w A | C12: X | E12: Hygiene | I12: Drinks w A | J12: X | L12: Hygiene | N12: X | P12: Drinks w A | Q12: X | S12: Hygiene | U12: X | W12: Drinks w A | X12: X | Z12: Hygiene | AB12: X | AD12: Drinks w A | AE12: X | AG12: Hygiene | AI12: X
B13: Sugary (dry) | C13: X | E13: Cosmetics | I13: Sugary (dry) | J13: X | L13: Cosmetics | P13: Sugary (dry) | Q13: X | S13: Cosmetics | W13: Sugary (dry) | X13: X | Z13: Cosmetics | AB13: X | AD13: Sugary (dry) | AE13: X | AG13: Cosmetics | AI13: X
B14: Sugary (fresh) | C14: X | E14: Kids items | I14: Sugary (fresh) | J14: X | L14: Kids items | P14: Sugary (fresh) | Q14: X | S14: Kids items | W14: Sugary (fresh) | X14: X | Z14: Kids items | AB14: X | AD14: Sugary (fresh) | AE14: X | AG14: Kids items
B15: Salty (dry) | C15: X | E15: Ready-to-wear | I15: Salty (dry) | J15: X | L15: Ready-to-wear | P15: Salty (dry) | Q15: X | S15: Ready-to-wear | W15: Salty (dry) | X15: X | Z15: Ready-to-wear | AD15: Salty (dry) | AE15: X | AG15: Ready-to-wear
B16: Salty (fresh) | C16: X | E16: Accessories | I16: Salty (fresh) | J16: X | L16: Accessories | N16: X | P16: Salty (fresh) | Q16: X | S16: Accessories | W16: Salty (fresh) | X16: X | Z16: Accessories | AD16: Salty (fresh) | AE16: X | AG16: Accessories
B17: Gourmet | E17: Souvenirs | I17: Gourmet | L17: Souvenirs | N17: X | P17: Gourmet | S17: Souvenirs | W17: Gourmet | X17: X | Z17: Souvenirs | AD17: Gourmet | AE17: X | AG17: Souvenirs | AI17: X
B20: CAISSE | C20: 1 | I20: CAISSE | J20: 1 | P20: CAISSE | Q20: 1 | W20: CAISSE | X20: 1 | AD20: CAISSE | AE20: 1
B21: VITRINE | C21: 1 | I21: VITRINE | J21: 1 | P21: VITRINE | Q21: 1 | W21: VITRINE | X21: 1 | AD21: VITRINE | AE21: 1
B22: AGENCEMENT | C22: Classic | E22: + Testé en "Premium" | I22: AGENCEMENT | J22: Classic | L22: + Testé en "Premium" | P22: AGENCEMENT | Q22: Classic | S22: + Testé en "Premium" | W22: AGENCEMENT | X22: Premium | Z22: + Testé en "Classic" | AD22: AGENCEMENT | AE22: Premium | AG22: + Testé en "Classic"
B25: REVENUS | C25: THOMAS | E25: ROD | I25: REVENUS | J25: THOMAS | L25: ROD | P25: REVENUS | Q25: THOMAS | S25: ROD | W25: REVENUS | X25: THOMAS | Z25: ROD | AD25: REVENUS | AE25: THOMAS | AG25: ROD
B27: F&B | C27: 600 | E27: 600 | F27: /mois | I27: F&B | J27: 74 | L27: 74 | M27: /mois | P27: F&B | Q27: 447 | S27: 447 | T27: /mois | W27: F&B | X27: 433 | Z27: 433 | AA27: /mois | AD27: F&B | AE27: 471 | AG27: 471 | AH27: /mois
B28: NON-F&B | C28: -277 | E28: -276 | F28: /mois | I28: NON-F&B | J28: -4 | L28: -4 | M28: /mois | P28: NON-F&B | Q28: -123 | S28: -123 | T28: /mois | W28: NON-F&B | X28: 129 | Z28: 129 | AA28: /mois | AD28: NON-F&B | AE28: 131 | AG28: 132 | AH28: /mois
B29: TOTAL | C29: =SUM(C27:C28) -> 323 | E29: 324 | F29: /mois | I29: TOTAL | J29: =SUM(J27:J28) -> 70 | L29: 70 | M29: /mois | P29: TOTAL | Q29: =SUM(Q27:Q28) -> 324 | S29: 325 | T29: /mois | W29: TOTAL | X29: =SUM(X27:X28) -> 562 | Z29: 562 | AA29: /mois | AD29: TOTAL | AE29: =SUM(AE27:AE28) -> 602 | AG29: 602 | AH29: /mois
B32: MARGE NETTE | C32: 105 | E32: N/A | F32: /mois | I32: MARGE NETTE | J32: -133 | L32: N/A | M32: /mois | P32: MARGE NETTE | Q32: 59 | S32: N/A | T32: /mois | W32: MARGE NETTE | X32: 106 | Z32: N/A | AA32: /mois | AD32: MARGE NETTE | AE32: 127 | AG32: N/A | AH32: /mois
B33: AMORTISSEMENT | C33: 115 | E33: N/A | F33: mois | I33: AMORTISSEMENT | J33: N/A | L33: N/A | M33: mois | P33: AMORTISSEMENT | Q33: 205 | S33: N/A | T33: mois | W33: AMORTISSEMENT | X33: 135 | Z33: N/A | AA33: mois | AD33: AMORTISSEMENT | AE33: 113 | AG33: N/A | AH33: mois

Sheet TESTS CONNECTED
B2: CONNECTED
B4: H5023 | C4: IBIS BUDGET TOURS GARE | I4: H0914 | J4: IBIS STYLES ROCHELLE CENTRE | P4: H0714 | Q4: IBIS AIX EN PROVENCE | W4: H0589 | X4: NOVOTEL METZ CENTRE | AD4: H1249 | AE4: MERCURE RENNES CENTRE GARE
B6: NB. CH. | C6: 95 | E6: ML | G6: 2 | I6: NB. CH. | J6: 82 | L6: ML | N6: 3 | P6: NB. CH. | Q6: 124 | S6: ML | U6: 3 | W6: NB. CH. | X6: 120 | Z6: ML | AB6: 3 | AD6: NB. CH. | AE6: 142 | AG6: ML | AI6: 4
B7: NB. G / CH. | C7: 1.5 | E7: F&B | G7: 0.9 | I7: NB. G / CH. | J7: 1.5 | L7: F&B | N7: 0.7 | P7: NB. G / CH. | Q7: 1.5 | S7: F&B | U7: 0.8 | W7: NB. G / CH. | X7: 1.5 | Z7: F&B | AB7: 0.7 | AD7: NB. G / CH. | AE7: 1.5 | AG7: F&B | AI7: 0.7
B8: TO (YTD) | C8: 0.7 | E8: N-F&B | G8: 0.1 | I8: TO (YTD) | J8: 0.7 | L8: N-F&B | N8: 0.3 | P8: TO (YTD) | Q8: 0.7 | S8: N-F&B | U8: 0.2 | W8: TO (YTD) | X8: 0.7 | Z8: N-F&B | AB8: 0.3 | AD8: TO (YTD) | AE8: 0.7 | AG8: N-F&B | AI8: 0.3
B11: Drinks w-out A | C11: X | E11: SOS | G11: X | I11: Drinks w-out A | J11: X | L11: SOS | N11: X | P11: Drinks w-out A | Q11: X | S11: SOS | U11: X | W11: Drinks w-out A | X11: X | Z11: SOS | AB11: X | AD11: Drinks w-out A | AE11: X | AG11: SOS | AI11: X
B12: Drinks w A | C12: X | E12: Hygiene | I12: Drinks w A | J12: X | L12: Hygiene | N12: X | P12: Drinks w A | Q12: X | S12: Hygiene | U12: X | W12: Drinks w A | X12: X | Z12: Hygiene | AB12: X | AD12: Drinks w A | AE12: X | AG12: Hygiene | AI12: X
B13: Sugary (dry) | C13: X | E13: Cosmetics | I13: Sugary (dry) | J13: X | L13: Cosmetics | P13: Sugary (dry) | Q13: X | S13: Cosmetics | W13: Sugary (dry) | X13: X | Z13: Cosmetics | AB13: X | AD13: Sugary (dry) | AE13: X | AG13: Cosmetics | AI13: X
B14: Sugary (fresh) | C14: X | E14: Kids items | I14: Sugary (fresh) | J14: X | L14: Kids items | P14: Sugary (fresh) | Q14: X | S14: Kids items | W14: Sugary (fresh) | X14: X | Z14: Kids items | AB14: X | AD14: Sugary (fresh) | AE14: X | AG14: Kids items
B15: Salty (dry) | C15: X | E15: Ready-to-wear | I15: Salty (dry) | J15: X | L15: Ready-to-wear | P15: Salty (dry) | Q15: X | S15: Ready-to-wear | W15: Salty (dry) | X15: X | Z15: Ready-to-wear | AD15: Salty (dry) | AE15: X | AG15: Ready-to-wear
B16: Salty (fresh) | C16: X | E16: Accessories | I16: Salty (fresh) | J16: X | L16: Accessories | N16: X | P16: Salty (fresh) | Q16: X | S16: Accessories | W16: Salty (fresh) | X16: X | Z16: Accessories | AD16: Salty (fresh) | AE16: X | AG16: Accessories
B17: Gourmet | E17: Souvenirs | I17: Gourmet | L17: Souvenirs | N17: X | P17: Gourmet | S17: Souvenirs | W17: Gourmet | X17: X | Z17: Souvenirs | AD17: Gourmet | AE17: X | AG17: Souvenirs | AI17: X
B20: FRIGO | C20: 1 | I20: CAISSE | J20: 1 | P20: CAISSE | Q20: 1 | W20: CAISSE | X20: 1 | AD20: CAISSE | AE20: 1
I21: VITRINE | J21: 1 | P21: VITRINE | Q21: 1 | W21: VITRINE | X21: 1 | AD21: VITRINE | AE21: 1
B22: AGENCEMENT | C22: Classic | E22: + Testé en "Premium" | I22: AGENCEMENT | J22: Classic | L22: + Testé en "Premium" | P22: AGENCEMENT | Q22: Classic | S22: + Testé en "Premium" | W22: AGENCEMENT | X22: Premium | Z22: + Testé en "Classic" | AD22: AGENCEMENT | AE22: Premium | AG22: + Testé en "Classic"
B25: REVENUS | C25: THOMAS | E25: ROD | I25: REVENUS | J25: THOMAS | L25: ROD | P25: REVENUS | Q25: THOMAS | S25: ROD | W25: REVENUS | X25: THOMAS | Z25: ROD | AD25: REVENUS | AE25: THOMAS | AG25: ROD
B27: F&B | F27: /mois | I27: F&B | M27: /mois | P27: F&B | T27: /mois | W27: F&B | AA27: /mois | AD27: F&B | AH27: /mois
B28: NON-F&B | F28: /mois | I28: NON-F&B | M28: /mois | P28: NON-F&B | T28: /mois | W28: NON-F&B | AA28: /mois | AD28: NON-F&B | AH28: /mois
B29: TOTAL | C29: =SUM(C27:C28) -> 0 | F29: /mois | I29: TOTAL | J29: =SUM(J27:J28) -> 0 | M29: /mois | P29: TOTAL | Q29: =SUM(Q27:Q28) -> 0 | T29: /mois | W29: TOTAL | X29: =SUM(X27:X28) -> 0 | AA29: /mois | AD29: TOTAL | AE29: =SUM(AE27:AE28) -> 0 | AH29: /mois
B32: MARGE NETTE | F32: /mois | I32: MARGE NETTE | M32: /mois | P32: MARGE NETTE | T32: /mois | W32: MARGE NETTE | AA32: /mois | AD32: MARGE NETTE | AH32: /mois
B33: AMORTISSEMENT | F33: mois | I33: AMORTISSEMENT | M33: mois | P33: AMORTISSEMENT | T33: mois | W33: AMORTISSEMENT | AA33: mois | AD33: AMORTISSEMENT | AH33: mois
B35: >> à compléter

Sheet CORRECTIONS ND
B2: CORRECTIONS NET DEVICES - 30/10/2025
B4: - Modifier marges produits et coûts dans le back-office
B5: - Afficher plutôt "Not profitable" si revenus négatifs (F&B ou NON-F&B ou TOTAL)
B6: - Attention la somme de F&B et NON-F&B ne fait pas exactement le montant affiché
B7: - Si "refresh" ou si modification d'une des variables alors = l'écran doit automatiquement affiché de nouveau la solution recommandée
B8: - Le slider F&B doit être à 0% lorsque tous les toggles sont OFF (ou message d'erreur)
B9: - Logos hôtels pas tout le temps corrects
B10: - Mise à jour automatique en modifiant le nb. de machines et l'agencement
B11: - Modifier la couleur du ou des toggles + du curseur/slider (barre + rond) en rouge (#DC2C3E) dès lors que ROD a modifié des paramètres automatiquement pour faire en sorte que le résultat soit positif
B12: - Modifier le composant heure/minutes dans l'étape #2 (ou le fixer)

Sheet DATA
B2: CATEGORIE | C2: DATA | D2: SOURCE ACTUELLE | E2: CONTACT / REFERENT | F2: N+1 CONTACT / REFERENT | G2: API ? | H2: STOCKAGE / OUTIL | I2: EQUIPE RESPONSABLE | J2: COMMENTAIRE THOMAS (INNOLAB)
B3: HOTEL | C3: CODE H | D3: 360 Hotel Referential | E3: Benoit SALMON | F3: François-Xavier MILLE
C4: NOM DE L'HOTEL | D4: 360 Hotel Referential | E4: Benoit SALMON | F4: François-Xavier MILLE
B5: GENERAL INFORMATION | C5: MARQUE | D5: 360 Hotel Referential | E5: Benoit SALMON | F5: François-Xavier MILLE | G5: API Portfolio | J5: Taki IDER + Delphine BAROUX + Jennifer WINSTON (WeMax)
C6: BUILT | D6: 360 Hotel Referential | E6: Benoit SALMON | F6: François-Xavier MILLE | G6: API Portfolio | J6: Taki IDER + Delphine BAROUX + Jennifer WINSTON (WeMax)
C7: NB. DE CHAMBRES | D7: 360 Hotel Referential | E7: Benoit SALMON | F7: François-Xavier MILLE | G7: API Portfolio | J7: Taki IDER + Delphine BAROUX + Jennifer WINSTON (WeMax)
B8: LOCALISATION | C8: ADRESSE POSTALE (1) | D8: Parc Hôtel Southern Europe | E8: - | F8: -
C9: ADRESSE POSTALE (2) | D9: Parc Hôtel Southern Europe | E9: - | F9: -
C10: ADRESSE POSTALE (3) | D10: Parc Hôtel Southern Europe | E10: - | F10: -
C11: CODE POSTAL | D11: Parc Hôtel Southern Europe | E11: - | F11: -
C12: VILLE | D12: VILLE | E12: Benoit SALMON
C13: LONGITUDE | D13: Export à la demande | E13: Rémy LEROY | F13: Arnaud THULLIEZ
C14: LATITUDE | D14: Export à la demande
C15: LOCATION | D15: Données fictives pour le moment | E15: - | F15: -
B16: OTHER INFORMATION | C16: HOTEL LAST RENOVATION | D16: Données fictives pour le moment | E16: - | F16: -
C17: LOBBY LAST RENOVATION | D17: Données fictives pour le moment | E17: - | F17: -
C18: CONTRAT | D18: 360 Hotel Referential | E18: Benoit SALMON | F18: François-Xavier MILLE | H18: MEGA ou WeMax | J18: Taki IDER + Delphine BAROUX + Jennifer WINSTON (WeMax)
C19: OWNER | D19: 360 Hotel Referential | E19: Benoit SALMON | F19: François-Xavier MILLE | H19: MEGA ou WeMax | J19: Taki IDER + Delphine BAROUX + Jennifer WINSTON (WeMax)
C20: DOM/DOF | D20: 360 Hotel Referential | E20: Benoit SALMON | F20: François-Xavier MILLE | H20: MEGA ou WeMax | J20: Taki IDER + Delphine BAROUX + Jennifer WINSTON (WeMax)
C21: PMS | D21: 360 Hotel Referential | E21: Benoit SALMON | F21: François-Xavier MILLE | G21: API Portfolio | J21: Taki IDER + Delphine BAROUX + Jennifer WINSTON (WeMax)
B22: BUSINESS INFORMATION | C22: # GUESTS PER ROOM | D22: Données fictives pour le moment | E22: - | F22: - | J22: Elias TANNOURY + Sylvain SETRAKIAN + Geetanjali ROGBEER
C23: YTD OCC. RATE | D23: Données fictives pour le moment | E23: - | F23: - | J23: Elias TANNOURY + Sylvain SETRAKIAN + Geetanjali ROGBEER
C24: LOWEST (MONTH) | D24: Données fictives pour le moment | E24: - | F24: - | J24: Elias TANNOURY + Sylvain SETRAKIAN + Geetanjali ROGBEER
C25: LOWEST (RATE) | D25: Données fictives pour le moment | E25: - | F25: - | J25: Elias TANNOURY + Sylvain SETRAKIAN + Geetanjali ROGBEER
C26: HIGHEST (MONTH) | D26: Données fictives pour le moment | E26: - | F26: - | J26: Elias TANNOURY + Sylvain SETRAKIAN + Geetanjali ROGBEER
C27: HIGHEST (RATE) | D27: Données fictives pour le moment | E27: - | F27: - | J27: Elias TANNOURY + Sylvain SETRAKIAN + Geetanjali ROGBEER
B28: SERVICES | C28: BAR | D28: 360 Hotel Referential | E28: Benoit SALMON | F28: François-Xavier MILLE | J28: Vanessa PACINI
C29: RESTAURANT | D29: 360 Hotel Referential | E29: Benoit SALMON | F29: François-Xavier MILLE | J29: Vanessa PACINI
C30: ROOM-SERVICE | D30: Données fictives pour le moment | E30: - | F30: -
C31: MINIBAR | D31: Données fictives pour le moment | E31: - | F31: -
C32: MEETING ROOMS | D32: 360 Hotel Referential | E32: Benoit SALMON | F32: François-Xavier MILLE | J32: Vanessa PACINI
C33: FITNESS | D33: 360 Hotel Referential | E33: Benoit SALMON | F33: François-Xavier MILLE | J33: Vanessa PACINI
C34: SPA | D34: 360 Hotel Referential | E34: Benoit SALMON | F34: François-Xavier MILLE | J34: Vanessa PACINI
C35: POOL | D35: 360 Hotel Referential | E35: Benoit SALMON | F35: François-Xavier MILLE | J35: Vanessa PACINI
B36: GUEST PROFILING | C36: NATIONAL | D36: Données fictives pour le moment | E36: - | F36: - | J36: Elias TANNOURY + Sylvain SETRAKIAN + Geetanjali ROGBEER
C37: INTERNATIONAL | D37: Données fictives pour le moment | E37: - | F37: - | J37: Elias TANNOURY + Sylvain SETRAKIAN + Geetanjali ROGBEER
C38: LEISURE | D38: Données fictives pour le moment | E38: - | F38: - | J38: Elias TANNOURY + Sylvain SETRAKIAN + Geetanjali ROGBEER
C39: BUSINESS | D39: Données fictives pour le moment | E39: - | F39: - | J39: Elias TANNOURY + Sylvain SETRAKIAN + Geetanjali ROGBEER

Sheet PROTOTYPE
B2: PROTOTYPE - SIMULATEUR ROD + REGLES POUR RECO DU CONCEPT RETAIL
B4: HOTEL PARAMETERS | I4: RETAIL SPACE(S) | Q4: PRODUCT MIX
D6: min. | F6: max. | K6: min. | N6: max. | S6: min. | U6: max. | Z6: min. | AB6: max.
B7: Nb. of rooms | D7: 1 | E7: auto | F7: 1000 | I7: Name of the space | K7: liste déroulante | Q7: F&B | S7: 0 | T7: incrément 10% | U7: 1 | W7: NON-F&B | Z7: - | AA7: auto | AB7: -
B8: Nb. of guests /room | D8: 1 | E8: incrément 0,5 | F8: 6 | I8: Wall linear meters | K8: 2m | L8: incrément 1 | N8: 30m
B9: Average occ. rate | D9: 0 | E9: incrément 1 | F9: 1 | I9: Square meters | K9: - | L9: auto | M9: m² | N9: - | Q9: Drinks without alcohol | T9: X | W9: SOS | AA9: X
Q10: Drinks with alcohol | T10: X | W10: Hygiene | AA10: X
Q11: Sugary food (dry) | T11: X | W11: Cosmetics | AA11: X
Q12: Sugary food (fresh) | T12: X | W12: Souvenirs | AA12: X
Q13: Salty food (dry) | T13: X | W13: Kids items | AA13: X
Q14: Salty food (fresh) | T14: X | W14: Ready-to-wear | AA14: X
Q15: Gourmet food | T15: X | W15: Accessories | AA15: X
B17: REGLES CONCERNANT LES PARAMETRES CI-DESSUS
B19: No specific rules | I19: Wall linear meters 1. En fonction du nom de l'espace sélectionné par l'hôtel dans la liste déroulante, les données correspondantes (mètres linéaires et m²) s'affichent automatiquement. 2. Les m² se calculent automatiquement en fonction du nombre de mètres linéaires affichés (qui peut être modifié par l'hôtel lors de sa simulation). 3. La règle est que la profondeur moyenne d'une boutique est de 1m (exemple : un espace avec 6 mètres linéaires fera automatiquement 6m²).
V27: Influence des catégories choisies/sélectionnées sur la projection de CA
V29: Si la catégorie est cochée +X%
V30: Si la catégorie n'est pas cochée -X%
V32: >> Voir le % associé à chaque catégorie dans l'onglet "PROJECTIONS"
B35: PROPOSED AUTONOMOUS SOLUTIONS >> MATERIEL
B37: Les trois solutions (types de boutique) s'affichent >> voir design proposé par Sylvain >> bouton "NEXT OPTIONS".
B38: La solution (type de boutique) qui s'affichera en premier, sera la solution recommandée par l'Innovation Lab en fonction des paramètres qui seront indiqués/complétés par l'hôtel dans le simulateur.
B39: Une seule solution à la fois peut-être sélectionnée par l'hôtel afin d'obtenir les résultats du simulateur (CA F&B, CA NON-F&B…).
B41: SIMPLY STORE | K41: LIBERTY STORE | U41: CONNECTED STORE
B43: Explications du concept (à confirmer si suffisamment de place) | K43: Explications du concept (à confirmer si suffisamment de place) | U43: Explications du concept (à confirmer si suffisamment de place)
V45: Le "FRIGO FROID" s'affiche seulement si l'hôtel a indiqué vouloir mettre du F&B dans son PRODUCT MIX (min. 10% car incrément de 10%)
D48: min. | F48: max. | O48: min. | R48: max.
D49: 1 | E49: incrément 1 | F49: no max | O49: 1 | Q49: incrément 1 | R49: no max
X50: FRIGO FROID
C51: Règle : | L51: Règle :
C52: 1 scanner minimum obligatoire | L52: 1 caisse minimum obligatoire
C53: Par défaut, le "sélecteur" est sur 1 | L53: Par défaut, le "sélecteur" est sur 1
X54: min. | AA54: max.
X55: 0 | Y55: incrément 1 | AA55: no max
C56: La partie ci-dessous s'affiche seulement si l'hôtel a indiqué vouloir mettre du F&B dans son PRODUCT MIX (min. 10% car incrément de 10%) | L56: La partie ci-dessous s'affiche seulement si l'hôtel a indiqué vouloir mettre du F&B dans son PRODUCT MIX (min. 10% car incrément de 10%)
V57: Règle :
V58: Par défaut, le "sélecteur" est sur 1 si F&B (sinon 0)
C63: Disposez-vous déjà d'une vitrine réfrigérée disponible pour votre future boutique autonome ? | L63: Disposez-vous déjà d'une vitrine réfrigérée disponible pour votre future boutique autonome ? | V63: Le "FRIGO AMBIANT" s'affiche seulement si l'hôtel a indiqué vouloir mettre du NON-F&B dans son PRODUCT MIX (min. 10% car incrément de 10%)
C65: ↳ Information récupérée à partir des étapes précédentes complétées par l'hôtel | L65: ↳ Information récupérée à partir des étapes précédentes complétées par l'hôtel
X68: FRIGO AMBIANT
C69: SI OUI | L69: SI OUI
...
