Workbook

Sheet SIMULATEUR SIMPLY
B2: SIMULATEUR ROD : REVENUS / MARGE NETTE / AMORTISSEMENT
B4: SIMPLY STORE
B5: MOYENNE RESULTATS PILOTE (ajouter résultats hôtels vente en réception) | L5: SIMULATEUR
B7: PARAMETRES HOTEL | E7: RETAIL SPACE | H7: MIX + MARGE PDTS | L7: PARAMETRES HOTEL | O7: RETAIL SPACE | R7: MIX + MARGE PDTS
J8: Marge | T8: Marge
B9: Nb. de ch. | C9: 129 | E9: M. lin. | F9: 6 | H9: F&B | I9: 0.4 | J9: 2.6 | L9: Nb. de ch. | M9: 100 | O9: M. lin. | P9: 3 | R9: F&B | S9: 0.7 | T9: 2.6
B10: Nb. gu / ch | C10: 1.7 | H10: N-F&B | I10: 0.6 | J10: 1.45 | L10: Nb. gu / ch. | M10: 1.5 | R10: N-F&B | S10: 0.3 | T10: 1.45
B11: TO (YTD) | C11: 0.8 | H11: Marge pondérée | J11: =SUMPRODUCT(J9:J10,I9:I10)/SUM(I9:I10) -> 1.91 | L11: TO (YTD) | M11: 0.8 | R11: Marge pondérée | T11: =SUMPRODUCT(T9:T10,S9:S10)/SUM(S9:S10) -> 2.255
B13: MOYENNE | L13: MOYENNE
B15: Ch. occ. | C15: =C9*C11 -> 103.2 | D15: chambres occupées | L15: Ch. occ. | M15: =M9*M11 -> 80 | N15: chambres occupées
B16: Cl. héb. | C16: =(C10*C9)*C11 -> 175.44 | D16: clients hébergés / jour | L16: Cl. héb. | M16: =(M10*M9)*M11 -> 120 | N16: clients hébergés / jour
B17: Cl. héb. | C17: =C16*30.5 -> 5350.92 | D17: clients hébergés / mois | L17: Cl. héb. | M17: =M16*30.5 -> 3660 | N17: clients hébergés / mois
B19: Nb. ventes | C19: 231 | D19: ventes mensuelles (résultat pilotes) | L19: Nb. ventes | M19: =M17*$C$21 -> 158.00274 | N19: ventes mensuelles
C21: =C19/C17 -> 0.043170146 | D21: de clients acheteurs / mois
B24: REGLE N°1
B25: REVENUS CALCULES EN FONCTION DU NB. DE CLIENTS ACHETEURS
B27: REGLE 1 = | C27: Chaque client acheteur génère du CA.
C28: Les montants de CA ci-dessous sont basés sur le résultat des pilotes SIMPLY.
C31: =C17*$C$21 -> 231 | E31: clients acheteurs / mois | M31: =M17*$C$21 -> 158.00274 | N31: clients acheteurs / mois
E33: CA HT | H33: CA TTC | O33: CA HT
C34: F&B | E34: 533 | H34: 587 | M34: F&B | O34: =($M$31*E34)/$C$31 -> 364.56908
C35: N-F&B | E35: 187 | H35: 224 | M35: N-F&B | O35: =($M$31*E35)/$C$31 -> 127.90698
B38: REGLE N°2
B39: REVENUS POUR 10% (DE PLUS OU DE MOINS) DE MIX PRODUITS
B41: REGLE 2 = | C41: Chaque 10% de MIX PDT en plus ou en moins impacte le CA.
C42: Cette règle impacte le CA F&B et le CA N-F&B, aussi bien en "bonus" qu'en "malus" pour chaque 10% de plus ou de moins par rapport au MIX PDT DE REFERENCE du SIMPLY STORE. | M42: Diff. F&B | O42: =S9-I9 -> 0.3
M43: Nb. de x 10% | O43: =O42*10 -> 3
M44: F&B add. | O44: =(E51*O43) -> 399.75
C46: ↓ | M46: Diff. N-F&B | O46: =S10-I10 -> -0.3
M47: Nb. de x 10% | O47: =O46*10 -> -3
M48: N-F&B add. | O48: =(E52*O47) -> -93.5
E50: CA HT | H50: CA TTC | O50: CA HT
C51: F&B | E51: =(E34*10%)/$I$9 -> 133.25 | H51: =(H34*10%)/$I$9 -> 146.75 | M51: F&B | O51: =O34+O44 -> 764.31908
C52: N-F&B | E52: =(E35*10%)/$I$10 -> 31.166667 | H52: =(H35*10%)/$I$10 -> 37.333333 | M52: N-F&B | O52: =O35+O48 -> 34.406977
B55: REGLE N°3
B56: INFLUENCE DES CATEGORIES DE PRODUITS SELECTIONNEES PAR L'HOTEL
B58: REGLE 3 = | C58: Si la catégorie est cochée +X% sur le CA Si la catégorie n'est pas cochée -X% sur le CA
C62: CATEGORIES F&B | L62: CATEGORIES NON-F&B
C64: Drinks without alcohol | H64: 0.1 | I64: =H64/1 -> 0.1 | L64: SOS | O64: 0.08 | P64: =O64/1 -> 0.08
C65: Drinks with alcohol | H65: 0.05 | I65: =H65/1 -> 0.05 | L65: Hygiene | O65: 0.05 | P65: =O65/1 -> 0.05 | R65: 0.05
...

Sheet SIMULATEUR LIBERTY
B2: SIMULATEUR ROD : REVENUS / MARGE NETTE / AMORTISSEMENT
B4: LIBERTY STORE
B5: MOYENNE RESULTATS PILOTES | L5: SIMULATEUR
B7: PARAMETRES HOTEL | E7: RETAIL SPACE | H7: MIX + MARGE PDTS | L7: PARAMETRES HOTEL | O7: RETAIL SPACE | R7: MIX + MARGE PDTS
J8: Marge | T8: Marge
B9: Nb. de ch. | C9: 142 | E9: M. lin. | F9: 8 | H9: F&B | I9: 0.7 | J9: 2.6 | L9: Nb. de ch. | M9: 98 | O9: M. lin. | P9: 6 | R9: F&B | S9: 0.7 | T9: 2.6
B10: Nb. gu / ch | C10: 2.2 | H10: N-F&B | I10: 0.3 | J10: 2 | L10: Nb. gu / ch. | M10: 1.5 | R10: N-F&B | S10: 0.3 | T10: 1.45
B11: TO (YTD) | C11: 0.7 | H11: Marge pondérée | J11: =SUMPRODUCT(J9:J10,I9:I10)/SUM(I9:I10) -> 2.42 | L11: TO (YTD) | M11: 0.7 | R11: Marge pondérée | T11: =SUMPRODUCT(T9:T10,S9:S10)/SUM(S9:S10) -> 2.255
B13: MOYENNE | L13: MOYENNE
B15: Ch. occ. | C15: =C9*C11 -> 99.4 | D15: chambres occupées | L15: Ch. occ. | M15: =M9*M11 -> 68.6 | N15: chambres occupées
B16: Cl. héb. | C16: =(C10*C9)*C11 -> 218.68 | D16: clients hébergés / jour | L16: Cl. héb. | M16: =(M10*M9)*M11 -> 102.9 | N16: clients hébergés / jour
B17: Cl. héb. | C17: =C16*30.5 -> 6669.74 | D17: clients hébergés / mois | L17: Cl. héb. | M17: =M16*30.5 -> 3138.45 | N17: clients hébergés / mois
B19: Nb. ventes | C19: 312 | D19: ventes mensuelles (résultat pilotes) | L19: Nb. ventes | M19: =M17*$C$21 -> 146.81178 | N19: ventes mensuelles
C21: =C19/C17 -> 0.046778435 | D21: de clients acheteurs / mois
B24: REGLE N°1
B25: REVENUS CALCULES EN FONCTION DU NB. DE CLIENTS ACHETEURS
B27: REGLE 1 = | C27: Chaque client acheteur génère du CA.
C28: Les montants de CA ci-dessous sont basés sur le résultat des pilotes LIBERTY.
C31: =C17*$C$21 -> 312 | E31: clients acheteurs / mois | M31: =M17*$C$21 -> 146.81178 | N31: clients acheteurs / mois
E33: CA HT | H33: CA TTC | O33: CA HT
C34: F&B | E34: 1055 | H34: 1174 | M34: F&B | O34: =($M$31*E34)/$C$31 -> 496.43086
C35: N-F&B | E35: 424 | H35: 508 | M35: N-F&B | O35: =($M$31*E35)/$C$31 -> 199.51344
B38: REGLE N°2
B39: REVENUS POUR 10% (DE PLUS OU DE MOINS) DE MIX PRODUITS
B41: REGLE 2 = | C41: Chaque 10% de MIX PDT en plus ou en moins impacte le CA.
C42: Cette règle impacte le CA F&B et le CA N-F&B, aussi bien en "bonus" qu'en "malus" pour chaque 10% de plus ou de moins par rapport au MIX PDT DE REFERENCE du SIMPLY STORE. | M42: Diff. F&B | O42: =S9-I9 -> 0
M43: Nb. de x 10% | O43: =O42*10 -> 0
M44: F&B add. | O44: =(E51*O43) -> 0
C46: ↓ | M46: Diff. N-F&B | O46: =S10-I10 -> 0
M47: Nb. de x 10% | O47: =O46*10 -> 0
M48: N-F&B add. | O48: =(E52*O47) -> 0
E50: CA HT | H50: CA TTC | O50: CA HT
C51: F&B | E51: =(E34*10%)/$I$9 -> 150.71429 | H51: =(H34*10%)/$I$9 -> 167.71429 | M51: F&B | O51: =O34+O44 -> 496.43086
C52: N-F&B | E52: =(E35*10%)/$I$10 -> 141.33333 | H52: =(H35*10%)/$I$10 -> 169.33333 | M52: N-F&B | O52: =O35+O48 -> 199.51344
B55: REGLE N°3
B56: INFLUENCE DES CATEGORIES DE PRODUITS SELECTIONNEES PAR L'HOTEL
B58: REGLE 3 = | C58: Si la catégorie est cochée +X% sur le CA Si la catégorie n'est pas cochée -X% sur le CA
C62: CATEGORIES F&B | L62: CATEGORIES NON-F&B
C64: Drinks without alcohol | H64: 0.1 | I64: =H64/1 -> 0.1 | L64: SOS | O64: 0.08 | P64: =O64/1 -> 0.08
C65: Drinks with alcohol | H65: 0.05 | I65: =H65/1 -> 0.05 | L65: Hygiene | O65: 0.05 | P65: =O65/1 -> 0.05 | R65: 0.05
...

Sheet SIMULATEUR CONNECTED
B2: SIMULATEUR ROD : REVENUS / MARGE NETTE / AMORTISSEMENT
B4: CONNECTED STORE
B5: MOYENNE RESULTATS PILOTES | L5: SIMULATEUR
B7: PARAMETRES HOTEL | E7: RETAIL SPACE | H7: MIX + MARGE PDTS | L7: PARAMETRES HOTEL | O7: RETAIL SPACE | R7: MIX + MARGE PDTS
J8: Marge | T8: Marge
B9: Nb. de ch. | C9: 305 | E9: M. lin. | F9: 7 | H9: F&B | I9: 0.8 | J9: 2.6 | L9: Nb. de ch. | M9: 95 | O9: M. lin. | P9: 2 | R9: F&B | S9: 0.9 | T9: 2.6 | V9: 2.6
B10: Nb. gu / ch | C10: 1.8 | E10: Nb. FC | F10: 3 | H10: N-F&B | I10: 0.2 | J10: 1.8 | L10: Nb. gu / ch. | M10: 1.5 | O10: Frigo F | P10: 1 | R10: N-F&B | S10: 0.1 | T10: 1.45 | V10: 1.45
B11: TO (YTD) | C11: 0.75 | H11: Marge pondérée | J11: =SUMPRODUCT(J9:J10,I9:I10)/SUM(I9:I10) -> 2.44 | L11: TO (YTD) | M11: 0.7 | O11: Frigo A | P11: 0 | R11: Marge pondérée | T11: =SUMPRODUCT(T9:T10,S9:S10)/SUM(S9:S10) -> 2.485
B13: MOYENNE | L13: MOYENNE
B15: Ch. occ. | C15: =C9*C11 -> 228.75 | D15: chambres occupées | L15: Ch. occ. | M15: =M9*M11 -> 66.5 | N15: chambres occupées
B16: Cl. héb. | C16: =(C10*C9)*C11 -> 411.75 | D16: clients hébergés / jour | L16: Cl. héb. | M16: =(M10*M9)*M11 -> 99.75 | N16: clients hébergés / jour
B17: Cl. héb. | C17: =C16*30.5 -> 12558.375 | D17: clients hébergés / mois | L17: Cl. héb. | M17: =M16*30.5 -> 3042.375 | N17: clients hébergés / mois
B19: Nb. ventes | C19: 534 | D19: ventes mensuelles (résultat pilotes) | L19: Nb. ventes | M19: =M17*$C$21 -> 129.36612 | N19: ventes mensuelles
C21: =C19/C17 -> 0.042521425 | D21: de clients acheteurs / mois
B24: REGLE N°1
B25: REVENUS CALCULES EN FONCTION DU NB. DE CLIENTS ACHETEURS
B27: REGLE 1 = | C27: Chaque client acheteur génère du CA.
C28: Les montants de CA ci-dessous sont basés sur le résultat des pilotes LIBERTY.
C31: =C17*$C$21 -> 534 | E31: clients acheteurs / mois | M31: =M17*$C$21 -> 129.36612 | N31: clients acheteurs / mois
E33: CA HT | H33: CA TTC | O33: CA HT
C34: F&B | E34: 3503 | H34: 3696 | M34: F&B | O34: =($M$31*E34)/$C$31 -> 848.63206
C35: N-F&B | E35: 131 | H35: 138 | M35: N-F&B | O35: =($M$31*E35)/$C$31 -> 31.735883
B38: REGLE N°2
B39: REVENUS POUR 10% (DE PLUS OU DE MOINS) DE MIX PRODUITS
B41: REGLE 2 = | C41: Chaque 10% de MIX PDT en plus ou en moins impacte le CA.
C42: Cette règle impacte le CA F&B et le CA N-F&B, aussi bien en "bonus" qu'en "malus" pour chaque 10% de plus ou de moins par rapport au MIX PDT DE REFERENCE du SIMPLY STORE. | M42: Diff. F&B | O42: =S9-I9 -> 0.1
M43: Nb. de x 10% | O43: =O42*10 -> 1
M44: F&B add. | O44: =(E51*O43) -> 437.875
C46: ↓ | M46: Diff. N-F&B | O46: =S10-I10 -> -0.1
M47: Nb. de x 10% | O47: =O46*10 -> -1
M48: N-F&B add. | O48: =(E52*O47) -> -65.5
E50: CA HT | H50: CA TTC | O50: CA HT
C51: F&B | E51: =(E34*10%)/$I$9 -> 437.875 | H51: =(H34*10%)/$I$9 -> 462 | M51: F&B | O51: =O34+O44 -> 1286.5071
C52: N-F&B | E52: =(E35*10%)/$I$10 -> 65.5 | H52: =(H35*10%)/$I$10 -> 69 | M52: N-F&B | O52: =O35+O48 -> -33.764117
B55: REGLE N°3
B56: INFLUENCE DES CATEGORIES DE PRODUITS SELECTIONNEES PAR L'HOTEL
B58: REGLE 3 = | C58: Si la catégorie est cochée +X% sur le CA Si la catégorie n'est pas cochée -X% sur le CA
C62: CATEGORIES F&B | L62: CATEGORIES NON-F&B
C64: Drinks without alcohol | H64: 0.1 | I64: =H64/1 -> 0.1 | L64: SOS | O64: 0.08 | P64: =O64/1 -> 0.08
C65: Drinks with alcohol | H65: 0.05 | I65: =H65/1 -> 0.05 | L65: Hygiene | P65: =O65/1 -> 0 | R65: 0.05
...

Sheet COUTS - TECHNOS
B2: COÛTS ► TECHNOS | Y2: NB : Vérifier quels presta permettent de couper le groupe froid et indiquer aux hôtels que le frigo froid est recommandé !!
B4: SIMPLY STORE > BUY ONLY | I4: LIBERTY STORE > BUY OU LEASE | Q4: CONNECTED STORE > BUY OU LEASE
C6: SCANNER | J6: CAISSE | R6: FRIGO FROID
C7: 60 | D7: mois | E7: BUY | F7: MENSUEL | G7: Calcul du coût mensuel uniquement pour la mensualisation du résultat. | J7: 60 | K7: mois | L7: TOTAL | M7: BUY | N7: LEASE | O7: 0.2 | R7: 60 | S7: mois | T7: TOTAL | U7: BUY | V7: LEASE | W7: 0.2
C8: 1 | D8: scan | E8: 500 | F8: =E8/$C$7 -> 8.3333333 | J8: 1 | K8: cai. | L8: =N8*$J$7 -> 15000 | M8: =L8-(L8*$O$7) -> 12000 | N8: 250 | O8: Le matériel coûte moins cher à l'achat (~20% moins cher) qu'avec un contrat de leasing sur 60 mois. | R8: 1 | S8: frig. | T8: =V8*$R$7 -> 27000 | U8: =T8-(T8*$W$7) -> 21600 | V8: 450 | W8: Le matériel coûte moins cher à l'achat (~20% moins cher) qu'avec un contrat de leasing sur 60 mois.
C9: 2 | D9: scan | E9: =$E$8*C9 -> 1000 | F9: =E9/$C$7 -> 16.666667 | J9: 2 | K9: cai. | L9: =N9*$J$7 -> 30000 | M9: =L9-(L9*$O$7) -> 24000 | N9: =$N$8*J9 -> 500 | R9: 2 | S9: frig. | T9: =V9*$R$7 -> 54000 | U9: =T9-(T9*$W$7) -> 43200 | V9: =$V$8*R9 -> 900
C10: 3 | D10: scan | E10: =$E$8*C10 -> 1500 | F10: =E10/$C$7 -> 25 | J10: 3 | K10: cai. | L10: =N10*$J$7 -> 45000 | M10: =L10-(L10*$O$7) -> 36000 | N10: =$N$8*J10 -> 750 | R10: 3 | S10: frig. | T10: =V10*$R$7 -> 81000 | U10: =T10-(T10*$W$7) -> 64800 | V10: =$V$8*R10 -> 1350
C11: 4 | D11: scan | E11: =$E$8*C11 -> 2000 | F11: =E11/$C$7 -> 33.333333 | J11: 4 | K11: cai. | L11: =N11*$J$7 -> 60000 | M11: =L11-(L11*$O$7) -> 48000 | N11: =$N$8*J11 -> 1000 | R11: 4 | S11: frig. | T11: =V11*$R$7 -> 108000 | U11: =T11-(T11*$W$7) -> 86400 | V11: =$V$8*R11 -> 1800
C13: VITRINE | J13: VITRINE | R13: FRIGO AMBIANT
C14: 60 | D14: mois | E14: BUY | F14: MENSUEL | G14: Calcul du coût mensuel uniquement pour la mensualisation du résultat. | J14: 60 | K14: mois | L14: TOTAL | M14: BUY | N14: LEASE | O14: 0.2 | R14: 60 | S14: mois | T14: TOTAL | U14: BUY | V14: LEASE | W14: 0.2
C15: 1 | D15: vitr. | E15: 800 | F15: =E15/$C$14 -> 13.333333 | J15: 1 | K15: vitr. | L15: 800 | M15: =L15-(L15*$O$14) -> 640 | N15: =L15/$J$14 -> 13.333333 | O15: Le matériel coûte moins cher à l'achat (~20% moins cher) qu'avec un contrat de leasing sur 60 mois. | R15: 1 | S15: frig. | T15: =V15*$R$14 -> 24000 | U15: =T15-(T15*$W$14) -> 19200 | V15: 400 | W15: Le matériel coûte moins cher à l'achat (~20% moins cher) qu'avec un contrat de leasing sur 60 mois.
C16: 2 | D16: vitr. | E16: =$E$15*C16 -> 1600 | F16: =E16/$C$14 -> 26.666667 | J16: 2 | K16: vitr. | L16: =$L$15*J16 -> 1600 | M16: =L16-(L16*$O$14) -> 1280 | N16: =L16/$J$14 -> 26.666667 | R16: 2 | S16: frig. | T16: =V16*$R$14 -> 48000 | U16: =T16-(T16*$W$14) -> 38400 | V16: =$V$15*R16 -> 800
C17: 3 | D17: vitr. | E17: =$E$15*C17 -> 2400 | F17: =E17/$C$14 -> 40 | J17: 3 | K17: vitr. | L17: =$L$15*J17 -> 2400 | M17: =L17-(L17*$O$14) -> 1920 | N17: =L17/$J$14 -> 40 | R17: 3 | S17: frig. | T17: =V17*$R$14 -> 72000 | U17: =T17-(T17*$W$14) -> 57600 | V17: =$V$15*R17 -> 1200
C18: 4 | D18: vitr. | E18: =$E$15*C18 -> 3200 | F18: =E18/$C$14 -> 53.333333 | J18: 4 | K18: vitr. | L18: =$L$15*J18 -> 3200 | M18: =L18-(L18*$O$14) -> 2560 | N18: =L18/$J$14 -> 53.333333 | R18: 4 | S18: frig. | T18: =V18*$R$14 -> 96000 | U18: =T18-(T18*$W$14) -> 76800 | V18: =$V$15*R18 -> 1600
C20: LICENCE LOGICIELLE | J20: LICENCE LOGICIELLE | R20: LICENCE LOG.
C21: 60 | D21: mois | E21: TOTAL | F21: MENSUEL | G21: Licence réglée de façon mensuelle uniquement. | J21: 60 | K21: mois | M21: TOTAL | N21: MENSUEL | O21: Licence réglée de façon mensuelle uniquement. | R21: 60 | S21: mois | U21: TOTAL | V21: MENSUEL | W21: Licence réglée de façon mensuelle uniquement.
C22: 1 | D22: licen. | E22: =F22*$C$21 -> 3000 | F22: 50 | J22: 1 | K22: licen. | M22: =N22*$J$21 -> 3000 | N22: 50 | R22: 1 | S22: licen. | U22: inclus | V22: inclus
C24: FRAIS AD HOC | J24: FRAIS AD HOC | R24: FRAIS AD HOC
C25: 60 | D25: mois | E25: TOTAL | F25: MENSUEL | G25: Frais ad hoc réglés de façon one-shot uniquement. | J25: 60 | K25: mois | M25: TOTAL | N25: MENSUEL | O25: Frais ad hoc réglés de façon one-shot uniquement. | R25: 60 | S25: mois | U25: TOTAL | V25: MENSUEL | W25: Frais ad hoc réglés de façon one-shot uniquement.
C26: 1 | D26: frais | E26: 1000 | F26: =E26/$C$25 -> 16.666667 | J26: 1 | K26: frais | M26: 2000 | N26: =M26/$J$25 -> 33.333333 | R26: 1 | S26: frais | U26: 3000 | V26: =U26/$R$25 -> 50
C28: TOTAL | E28: =SUM(E8,E15,E22,E26) -> 5300 | F28: =SUM(F8,F15,F22,F26) -> 88.333333 | J28: TOTAL | M28: =SUM(M8,M15,M22,M26) -> 17640 | N28: =SUM(N8,N15,N22,N26) -> 346.66667 | R28: TOTAL | U28: =SUM(U8,U15,U22,U26) -> 43800 | V28: =SUM(V8,V15,V22,V26) -> 900

Sheet COUTS - ANNEXES
B2: COÛTS ► ANNEXES
B4: SIMPLY STORE | H4: LIBERTY STORE | N4: CONNECTED STORE
E6: ELECTRICITE | K6: ELECTRICITE | Q6: ELECTRICITE
C7: 60 | D7: mois | E7: TOTAL | F7: PAR MOIS | I7: 60 | J7: mois | K7: TOTAL | L7: PAR MOIS | O7: 60 | P7: mois | Q7: TOTAL | R7: PAR MOIS
C8: 1 | D8: scan | E8: =F8*$C$7 -> 120 | F8: 2 | I8: 1 | J8: cai. | K8: =L8*$I$7 -> 600 | L8: 10 | O8: 1 | P8: frig. | Q8: =R8*$O$7 -> 1200 | R8: 20
C9: 2 | D9: scan | E9: =F9*$C$7 -> 240 | F9: =$F$8*C9 -> 4 | I9: 2 | J9: cai. | K9: =L9*$I$7 -> 1200 | L9: =$L$8*I9 -> 20 | O9: 2 | P9: frig. | Q9: =R9*$O$7 -> 2400 | R9: =$R$8*O9 -> 40
C10: 3 | D10: scan | E10: =F10*$C$7 -> 360 | F10: =$F$8*C10 -> 6 | I10: 3 | J10: cai. | K10: =L10*$I$7 -> 1800 | L10: =$L$8*I10 -> 30 | O10: 3 | P10: frig. | Q10: =R10*$O$7 -> 3600 | R10: =$R$8*O10 -> 60
C11: 4 | D11: scan | E11: =F11*$C$7 -> 480 | F11: =$F$8*C11 -> 8 | I11: 4 | J11: cai. | K11: =L11*$I$7 -> 2400 | L11: =$L$8*I11 -> 40 | O11: 4 | P11: frig. | Q11: =R11*$O$7 -> 4800 | R11: =$R$8*O11 -> 80
E13: ELECTRICITE | K13: ELECTRICITE | Q13: ELECTRICITE
C14: 60 | D14: mois | E14: TOTAL | F14: PAR MOIS | I14: 60 | J14: mois | K14: TOTAL | L14: PAR MOIS | O14: 60 | P14: mois | Q14: TOTAL | R14: PAR MOIS
C15: 1 | D15: vitr. | E15: =F15*$C$14 -> 600 | F15: 10 | I15: 1 | J15: vitr. | K15: =L15*$I$14 -> 600 | L15: 10 | O15: 1 | P15: frig. | Q15: =R15*$O$14 -> 900 | R15: 15
C16: 2 | D16: vitr. | E16: =$E$15*C16 -> 1200 | F16: =$F$15*C16 -> 20 | I16: 2 | J16: vitr. | K16: =L16*$I$14 -> 1200 | L16: =$L$15*I16 -> 20 | O16: 2 | P16: frig. | Q16: =R16*$O$14 -> 1800 | R16: =$R$15*O16 -> 30
C17: 3 | D17: vitr. | E17: =$E$15*C17 -> 1800 | F17: =$F$15*C17 -> 30 | I17: 3 | J17: vitr. | K17: =L17*$I$14 -> 1800 | L17: =$L$15*I17 -> 30 | O17: 3 | P17: frig. | Q17: =R17*$O$14 -> 2700 | R17: =$R$15*O17 -> 45
C18: 4 | D18: vitr. | E18: =$E$15*C18 -> 2400 | F18: =$F$15*C18 -> 40 | I18: 4 | J18: vitr. | K18: =L18*$I$14 -> 2400 | L18: =$L$15*I18 -> 40 | O18: 4 | P18: frig. | Q18: =R18*$O$14 -> 3600 | R18: =$R$15*O18 -> 60
E20: PERSONNEL | K20: PERSONNEL | Q20: PERSONNEL
C21: 60 | D21: mois | E21: TOTAL | F21: PAR MOIS | I21: 60 | J21: mois | K21: TOTAL | L21: PAR MOIS | O21: 60 | P21: mois | Q21: TOTAL | R21: PAR MOIS
C22: 1 | D22: staff | E22: =F22*$C$21 -> 180 | F22: 3 | I22: 1 | J22: staff | K22: =L22*$I$21 -> 600 | L22: 10 | O22: 1 | P22: staff | Q22: =R22*$O$21 -> 600 | R22: 10
C24: TOTAL | E24: =SUM(E8,E15,E22) -> 900 | F24: =SUM(F8,F15,F22) -> 15 | I24: TOTAL | K24: =SUM(K8,K15,K22) -> 1800 | L24: =SUM(L8,L15,L22) -> 30 | O24: TOTAL | Q24: =SUM(Q8,Q15,Q22) -> 2700 | R24: =SUM(R8,R15,R22) -> 45

Sheet COUTS - AGENCEMENT
B2: COÛTS ► AGENCEMENT
B4: SIMPLY STORE | L4: LIBERTY STORE | V4: CONNECTED STORE
E6: CLASSIC | G6: PREMIUM | I6: BESPOKE | O6: CLASSIC | Q6: PREMIUM | S6: BESPOKE | Y6: CLASSIC | AA6: PREMIUM | AC6: BESPOKE
C7: 84 | D7: mois | E7: TOTAL | F7: PAR MOIS | G7: TOTAL | H7: PAR MOIS | I7: TOTAL | J7: PAR MOIS | M7: 84 | N7: mois | O7: TOTAL | P7: PAR MOIS | Q7: TOTAL | R7: PAR MOIS | S7: TOTAL | T7: PAR MOIS | W7: 84 | X7: mois | Y7: TOTAL | Z7: PAR MOIS | AA7: TOTAL | AB7: PAR MOIS | AC7: TOTAL | AD7: PAR MOIS
C8: 1 | D8: m | E8: 1000 | F8: =E8/$C$7 -> 11.904762 | G8: 1200 | H8: =G8/$C$7 -> 14.285714 | I8: 2200 | J8: =I8/$C$7 -> 26.190476 | M8: 1 | N8: m | O8: 1000 | P8: =O8/$M$7 -> 11.904762 | Q8: 1200 | R8: =Q8/$M$7 -> 14.285714 | S8: 2200 | T8: =S8/$M$7 -> 26.190476 | W8: 1 | X8: m | Y8: 800 | Z8: =Y8/$W$7 -> 9.5238095 | AA8: 1000 | AB8: =AA8/$W$7 -> 11.904762 | AC8: 1600 | AD8: =AC8/$W$7 -> 19.047619
C9: 2 | D9: m | E9: =$E$8*C9 -> 2000 | F9: =E9/$C$7 -> 23.809524 | G9: =$G$8*C9 -> 2400 | H9: =G9/$C$7 -> 28.571429 | I9: =$I$8*C9 -> 4400 | J9: =I9/$C$7 -> 52.380952 | M9: 2 | N9: m | O9: =$O$8*M9 -> 2000 | P9: =O9/$M$7 -> 23.809524 | Q9: =$Q$8*M9 -> 2400 | R9: =Q9/$M$7 -> 28.571429 | S9: =$S$8*M9 -> 4400 | T9: =S9/$M$7 -> 52.380952 | W9: 2 | X9: m | Y9: =$Y$8*W9 -> 1600 | Z9: =Y9/$W$7 -> 19.047619 | AA9: =$AA$8*W9 -> 2000 | AB9: =AA9/$W$7 -> 23.809524 | AC9: =$AC$8*W9 -> 3200 | AD9: =AC9/$W$7 -> 38.095238
C10: 3 | D10: m | E10: =$E$8*C10 -> 3000 | F10: =E10/$C$7 -> 35.714286 | G10: =$G$8*C10 -> 3600 | H10: =G10/$C$7 -> 42.857143 | I10: =$I$8*C10 -> 6600 | J10: =I10/$C$7 -> 78.571429 | M10: 3 | N10: m | O10: =$O$8*M10 -> 3000 | P10: =O10/$M$7 -> 35.714286 | Q10: =$Q$8*M10 -> 3600 | R10: =Q10/$M$7 -> 42.857143 | S10: =$S$8*M10 -> 6600 | T10: =S10/$M$7 -> 78.571429 | V10: IBB STRA | W10: 3 | X10: m | Y10: =$Y$8*W10 -> 2400 | Z10: =Y10/$W$7 -> 28.571429 | AA10: =$AA$8*W10 -> 3000 | AB10: =AA10/$W$7 -> 35.714286 | AC10: =$AC$8*W10 -> 4800 | AD10: =AC10/$W$7 -> 57.142857
C11: 4 | D11: m | E11: =$E$8*C11 -> 4000 | F11: =E11/$C$7 -> 47.619048 | G11: =$G$8*C11 -> 4800 | H11: =G11/$C$7 -> 57.142857 | I11: =$I$8*C11 -> 8800 | J11: =I11/$C$7 -> 104.7619 | M11: 4 | N11: m | O11: =$O$8*M11 -> 4000 | P11: =O11/$M$7 -> 47.619048 | Q11: =$Q$8*M11 -> 4800 | R11: =Q11/$M$7 -> 57.142857 | S11: =$S$8*M11 -> 8800 | T11: =S11/$M$7 -> 104.7619 | W11: 4 | X11: m | Y11: =$Y$8*W11 -> 3200 | Z11: =Y11/$W$7 -> 38.095238 | AA11: =$AA$8*W11 -> 4000 | AB11: =AA11/$W$7 -> 47.619048 | AC11: =$AC$8*W11 -> 6400 | AD11: =AC11/$W$7 -> 76.190476
C12: 5 | D12: m | E12: =$E$8*C12 -> 5000 | F12: =E12/$C$7 -> 59.52381 | G12: =$G$8*C12 -> 6000 | H12: =G12/$C$7 -> 71.428571 | I12: =$I$8*C12 -> 11000 | J12: =I12/$C$7 -> 130.95238 | M12: 5 | N12: m | O12: =$O$8*M12 -> 5000 | P12: =O12/$M$7 -> 59.52381 | Q12: =$Q$8*M12 -> 6000 | R12: =Q12/$M$7 -> 71.428571 | S12: =$S$8*M12 -> 11000 | T12: =S12/$M$7 -> 130.95238 | W12: 5 | X12: m | Y12: =$Y$8*W12 -> 4000 | Z12: =Y12/$W$7 -> 47.619048 | AA12: =$AA$8*W12 -> 5000 | AB12: =AA12/$W$7 -> 59.52381 | AC12: =$AC$8*W12 -> 8000 | AD12: =AC12/$W$7 -> 95.238095
B13: IBB NICE | C13: 6 | D13: m | E13: =$E$8*C13 -> 6000 | F13: =E13/$C$7 -> 71.428571 | G13: =$G$8*C13 -> 7200 | H13: =G13/$C$7 -> 85.714286 | I13: =$I$8*C13 -> 13200 | J13: =I13/$C$7 -> 157.14286 | M13: 6 | N13: m | O13: =$O$8*M13 -> 6000 | P13: =O13/$M$7 -> 71.428571 | Q13: =$Q$8*M13 -> 7200 | R13: =Q13/$M$7 -> 85.714286 | S13: =$S$8*M13 -> 13200 | T13: =S13/$M$7 -> 157.14286 | W13: 6 | X13: m | Y13: =$Y$8*W13 -> 4800 | Z13: =Y13/$W$7 -> 57.142857 | AA13: =$AA$8*W13 -> 6000 | AB13: =AA13/$W$7 -> 71.428571 | AC13: =$AC$8*W13 -> 9600 | AD13: =AC13/$W$7 -> 114.28571
B14: =I13/C13 -> 2200 | C14: 7 | D14: m | E14: =$E$8*C14 -> 7000 | F14: =E14/$C$7 -> 83.333333 | G14: =$G$8*C14 -> 8400 | H14: =G14/$C$7 -> 100 | I14: =$I$8*C14 -> 15400 | J14: =I14/$C$7 -> 183.33333 | L14: MER BOUL | M14: 7 | N14: m | O14: =$O$8*M14 -> 7000 | P14: =O14/$M$7 -> 83.333333 | Q14: =$Q$8*M14 -> 8400 | R14: =Q14/$M$7 -> 100 | S14: =$S$8*M14 -> 15400 | T14: =S14/$M$7 -> 183.33333 | V14: MER MONT | W14: 7 | X14: m | Y14: =$Y$8*W14 -> 5600 | Z14: =Y14/$W$7 -> 66.666667 | AA14: =$AA$8*W14 -> 7000 | AB14: =AA14/$W$7 -> 83.333333 | AC14: =$AC$8*W14 -> 11200 | AD14: =AC14/$W$7 -> 133.33333
C15: 8 | D15: m | E15: =$E$8*C15 -> 8000 | F15: =E15/$C$7 -> 95.238095 | G15: =$G$8*C15 -> 9600 | H15: =G15/$C$7 -> 114.28571 | I15: =$I$8*C15 -> 17600 | J15: =I15/$C$7 -> 209.52381 | M15: 8 | N15: m | O15: =$O$8*M15 -> 8000 | P15: =O15/$M$7 -> 95.238095 | Q15: =$Q$8*M15 -> 9600 | R15: =Q15/$M$7 -> 114.28571 | S15: =$S$8*M15 -> 17600 | T15: =S15/$M$7 -> 209.52381 | W15: 8 | X15: m | Y15: =$Y$8*W15 -> 6400 | Z15: =Y15/$W$7 -> 76.190476 | AA15: =$AA$8*W15 -> 8000 | AB15: =AA15/$W$7 -> 95.238095 | AC15: =$AC$8*W15 -> 12800 | AD15: =AC15/$W$7 -> 152.38095
C16: 9 | D16: m | E16: =$E$8*C16 -> 9000 | F16: =E16/$C$7 -> 107.14286 | G16: =$G$8*C16 -> 10800 | H16: =G16/$C$7 -> 128.57143 | I16: =$I$8*C16 -> 19800 | J16: =I16/$C$7 -> 235.71429 | L16: NOV MEG | M16: 9 | N16: m | O16: =$O$8*M16 -> 9000 | P16: =O16/$M$7 -> 107.14286 | Q16: =$Q$8*M16 -> 10800 | R16: =Q16/$M$7 -> 128.57143 | S16: =$S$8*M16 -> 19800 | T16: =S16/$M$7 -> 235.71429 | W16: 9 | X16: m | Y16: =$Y$8*W16 -> 7200 | Z16: =Y16/$W$7 -> 85.714286 | AA16: =$AA$8*W16 -> 9000 | AB16: =AA16/$W$7 -> 107.14286 | AC16: =$AC$8*W16 -> 14400 | AD16: =AC16/$W$7 -> 171.42857
C17: 10 | D17: m | E17: =$E$8*C17 -> 10000 | F17: =E17/$C$7 -> 119.04762 | G17: =$G$8*C17 -> 12000 | H17: =G17/$C$7 -> 142.85714 | I17: =$I$8*C17 -> 22000 | J17: =I17/$C$7 -> 261.90476 | M17: 10 | N17: m | O17: =$O$8*M17 -> 10000 | P17: =O17/$M$7 -> 119.04762 | Q17: =$Q$8*M17 -> 12000 | R17: =Q17/$M$7 -> 142.85714 | S17: =$S$8*M17 -> 22000 | T17: =S17/$M$7 -> 261.90476 | W17: 10 | X17: m | Y17: =$Y$8*W17 -> 8000 | Z17: =Y17/$W$7 -> 95.238095 | AA17: =$AA$8*W17 -> 10000 | AB17: =AA17/$W$7 -> 119.04762 | AC17: =$AC$8*W17 -> 16000 | AD17: =AC17/$W$7 -> 190.47619
C18: 11 | D18: m | E18: =$E$8*C18 -> 11000 | F18: =E18/$C$7 -> 130.95238 | G18: =$G$8*C18 -> 13200 | H18: =G18/$C$7 -> 157.14286 | I18: =$I$8*C18 -> 24200 | J18: =I18/$C$7 -> 288.09524 | M18: 11 | N18: m | O18: =$O$8*M18 -> 11000 | P18: =O18/$M$7 -> 130.95238 | Q18: =$Q$8*M18 -> 13200 | R18: =Q18/$M$7 -> 157.14286 | S18: =$S$8*M18 -> 24200 | T18: =S18/$M$7 -> 288.09524 | W18: 11 | X18: m | Y18: =$Y$8*W18 -> 8800 | Z18: =Y18/$W$7 -> 104.7619 | AA18: =$AA$8*W18 -> 11000 | AB18: =AA18/$W$7 -> 130.95238 | AC18: =$AC$8*W18 -> 17600 | AD18: =AC18/$W$7 -> 209.52381
C19: 12 | D19: m | E19: =$E$8*C19 -> 12000 | F19: =E19/$C$7 -> 142.85714 | G19: =$G$8*C19 -> 14400 | H19: =G19/$C$7 -> 171.42857 | I19: =$I$8*C19 -> 26400 | J19: =I19/$C$7 -> 314.28571 | M19: 12 | N19: m | O19: =$O$8*M19 -> 12000 | P19: =O19/$M$7 -> 142.85714 | Q19: =$Q$8*M19 -> 14400 | R19: =Q19/$M$7 -> 171.42857 | S19: =$S$8*M19 -> 26400 | T19: =S19/$M$7 -> 314.28571 | W19: 12 | X19: m | Y19: =$Y$8*W19 -> 9600 | Z19: =Y19/$W$7 -> 114.28571 | AA19: =$AA$8*W19 -> 12000 | AB19: =AA19/$W$7 -> 142.85714 | AC19: =$AC$8*W19 -> 19200 | AD19: =AC19/$W$7 -> 228.57143
C20: 13 | D20: m | E20: =$E$8*C20 -> 13000 | F20: =E20/$C$7 -> 154.7619 | G20: =$G$8*C20 -> 15600 | H20: =G20/$C$7 -> 185.71429 | I20: =$I$8*C20 -> 28600 | J20: =I20/$C$7 -> 340.47619 | M20: 13 | N20: m | O20: =$O$8*M20 -> 13000 | P20: =O20/$M$7 -> 154.7619 | Q20: =$Q$8*M20 -> 15600 | R20: =Q20/$M$7 -> 185.71429 | S20: =$S$8*M20 -> 28600 | T20: =S20/$M$7 -> 340.47619 | W20: 13 | X20: m | Y20: =$Y$8*W20 -> 10400 | Z20: =Y20/$W$7 -> 123.80952 | AA20: =$AA$8*W20 -> 13000 | AB20: =AA20/$W$7 -> 154.7619 | AC20: =$AC$8*W20 -> 20800 | AD20: =AC20/$W$7 -> 247.61905
C21: 14 | D21: m | E21: =$E$8*C21 -> 14000 | F21: =E21/$C$7 -> 166.66667 | G21: =$G$8*C21 -> 16800 | H21: =G21/$C$7 -> 200 | I21: =$I$8*C21 -> 30800 | J21: =I21/$C$7 -> 366.66667 | M21: 14 | N21: m | O21: =$O$8*M21 -> 14000 | P21: =O21/$M$7 -> 166.66667 | Q21: =$Q$8*M21 -> 16800 | R21: =Q21/$M$7 -> 200 | S21: =$S$8*M21 -> 30800 | T21: =S21/$M$7 -> 366.66667 | W21: 14 | X21: m | Y21: =$Y$8*W21 -> 11200 | Z21: =Y21/$W$7 -> 133.33333 | AA21: =$AA$8*W21 -> 14000 | AB21: =AA21/$W$7 -> 166.66667 | AC21: =$AC$8*W21 -> 22400 | AD21: =AC21/$W$7 -> 266.66667
C22: 15 | D22: m | E22: =$E$8*C22 -> 15000 | F22: =E22/$C$7 -> 178.57143 | G22: =$G$8*C22 -> 18000 | H22: =G22/$C$7 -> 214.28571 | I22: =$I$8*C22 -> 33000 | J22: =I22/$C$7 -> 392.85714 | M22: 15 | N22: m | O22: =$O$8*M22 -> 15000 | P22: =O22/$M$7 -> 178.57143 | Q22: =$Q$8*M22 -> 18000 | R22: =Q22/$M$7 -> 214.28571 | S22: =$S$8*M22 -> 33000 | T22: =S22/$M$7 -> 392.85714 | W22: 15 | X22: m | Y22: =$Y$8*W22 -> 12000 | Z22: =Y22/$W$7 -> 142.85714 | AA22: =$AA$8*W22 -> 15000 | AB22: =AA22/$W$7 -> 178.57143 | AC22: =$AC$8*W22 -> 24000 | AD22: =AC22/$W$7 -> 285.71429
C23: 16 | D23: m | E23: =$E$8*C23 -> 16000 | F23: =E23/$C$7 -> 190.47619 | G23: =$G$8*C23 -> 19200 | H23: =G23/$C$7 -> 228.57143 | I23: =$I$8*C23 -> 35200 | J23: =I23/$C$7 -> 419.04762 | M23: 16 | N23: m | O23: =$O$8*M23 -> 16000 | P23: =O23/$M$7 -> 190.47619 | Q23: =$Q$8*M23 -> 19200 | R23: =Q23/$M$7 -> 228.57143 | S23: =$S$8*M23 -> 35200 | T23: =S23/$M$7 -> 419.04762 | W23: 16 | X23: m | Y23: =$Y$8*W23 -> 12800 | Z23: =Y23/$W$7 -> 152.38095 | AA23: =$AA$8*W23 -> 16000 | AB23: =AA23/$W$7 -> 190.47619 | AC23: =$AC$8*W23 -> 25600 | AD23: =AC23/$W$7 -> 304.7619
C24: 17 | D24: m | E24: =$E$8*C24 -> 17000 | F24: =E24/$C$7 -> 202.38095 | G24: =$G$8*C24 -> 20400 | H24: =G24/$C$7 -> 242.85714 | I24: =$I$8*C24 -> 37400 | J24: =I24/$C$7 -> 445.2381 | M24: 17 | N24: m | O24: =$O$8*M24 -> 17000 | P24: =O24/$M$7 -> 202.38095 | Q24: =$Q$8*M24 -> 20400 | R24: =Q24/$M$7 -> 242.85714 | S24: =$S$8*M24 -> 37400 | T24: =S24/$M$7 -> 445.2381 | W24: 17 | X24: m | Y24: =$Y$8*W24 -> 13600 | Z24: =Y24/$W$7 -> 161.90476 | AA24: =$AA$8*W24 -> 17000 | AB24: =AA24/$W$7 -> 202.38095 | AC24: =$AC$8*W24 -> 27200 | AD24: =AC24/$W$7 -> 323.80952
C25: 18 | D25: m | E25: =$E$8*C25 -> 18000 | F25: =E25/$C$7 -> 214.28571 | G25: =$G$8*C25 -> 21600 | H25: =G25/$C$7 -> 257.14286 | I25: =$I$8*C25 -> 39600 | J25: =I25/$C$7 -> 471.42857 | M25: 18 | N25: m | O25: =$O$8*M25 -> 18000 | P25: =O25/$M$7 -> 214.28571 | Q25: =$Q$8*M25 -> 21600 | R25: =Q25/$M$7 -> 257.14286 | S25: =$S$8*M25 -> 39600 | T25: =S25/$M$7 -> 471.42857 | W25: 18 | X25: m | Y25: =$Y$8*W25 -> 14400 | Z25: =Y25/$W$7 -> 171.42857 | AA25: =$AA$8*W25 -> 18000 | AB25: =AA25/$W$7 -> 214.28571 | AC25: =$AC$8*W25 -> 28800 | AD25: =AC25/$W$7 -> 342.85714
C26: 19 | D26: m | E26: =$E$8*C26 -> 19000 | F26: =E26/$C$7 -> 226.19048 | G26: =$G$8*C26 -> 22800 | H26: =G26/$C$7 -> 271.42857 | I26: =$I$8*C26 -> 41800 | J26: =I26/$C$7 -> 497.61905 | M26: 19 | N26: m | O26: =$O$8*M26 -> 19000 | P26: =O26/$M$7 -> 226.19048 | Q26: =$Q$8*M26 -> 22800 | R26: =Q26/$M$7 -> 271.42857 | S26: =$S$8*M26 -> 41800 | T26: =S26/$M$7 -> 497.61905 | W26: 19 | X26: m | Y26: =$Y$8*W26 -> 15200 | Z26: =Y26/$W$7 -> 180.95238 | AA26: =$AA$8*W26 -> 19000 | AB26: =AA26/$W$7 -> 226.19048 | AC26: =$AC$8*W26 -> 30400 | AD26: =AC26/$W$7 -> 361.90476
C27: 20 | D27: m | E27: =$E$8*C27 -> 20000 | F27: =E27/$C$7 -> 238.09524 | G27: =$G$8*C27 -> 24000 | H27: =G27/$C$7 -> 285.71429 | I27: =$I$8*C27 -> 44000 | J27: =I27/$C$7 -> 523.80952 | M27: 20 | N27: m | O27: =$O$8*M27 -> 20000 | P27: =O27/$M$7 -> 238.09524 | Q27: =$Q$8*M27 -> 24000 | R27: =Q27/$M$7 -> 285.71429 | S27: =$S$8*M27 -> 44000 | T27: =S27/$M$7 -> 523.80952 | W27: 20 | X27: m | Y27: =$Y$8*W27 -> 16000 | Z27: =Y27/$W$7 -> 190.47619 | AA27: =$AA$8*W27 -> 20000 | AB27: =AA27/$W$7 -> 238.09524 | AC27: =$AC$8*W27 -> 32000 | AD27: =AC27/$W$7 -> 380.95238
C28: 21 | D28: m | E28: =$E$8*C28 -> 21000 | F28: =E28/$C$7 -> 250 | G28: =$G$8*C28 -> 25200 | H28: =G28/$C$7 -> 300 | I28: =$I$8*C28 -> 46200 | J28: =I28/$C$7 -> 550 | M28: 21 | N28: m | O28: =$O$8*M28 -> 21000 | P28: =O28/$M$7 -> 250 | Q28: =$Q$8*M28 -> 25200 | R28: =Q28/$M$7 -> 300 | S28: =$S$8*M28 -> 46200 | T28: =S28/$M$7 -> 550 | W28: 21 | X28: m | Y28: =$Y$8*W28 -> 16800 | Z28: =Y28/$W$7 -> 200 | AA28: =$AA$8*W28 -> 21000 | AB28: =AA28/$W$7 -> 250 | AC28: =$AC$8*W28 -> 33600 | AD28: =AC28/$W$7 -> 400
... C37: 30 | D37: m | E37: =$E$8*C37 -> 30000 | F37: =E37/$C$7 -> 357.14286 | G37: =$G$8*C37 -> 36000 | H37: =G37/$C$7 -> 428.57143 | I37: =$I$8*C37 -> 66000 | J37: =I37/$C$7 -> 785.71429 | M37: 30 | N37: m | O37: =$O$8*M37 -> 30000 | P37: =O37/$M$7 -> 357.14286 | Q37: =$Q$8*M37 -> 36000 | R37: =Q37/$M$7 -> 428.57143 | S37: =$S$8*M37 -> 66000 | T37: =S37/$M$7 -> 785.71429 | W37: 30 | X37: m | Y37: =$Y$8*W37 -> 24000 | Z37: =Y37/$W$7 -> 285.71429 | AA37: =$AA$8*W37 -> 30000 | AB37: =AA37/$W$7 -> 357.14286 | AC37: =$AC$8*W37 -> 48000 | AD37: =AC37/$W$7 -> 571.42857

Sheet REVENUS - MIX & MARGES
B2: REVENUS ► MIX PRODUITS
B4: SIMPLY STORE | G4: LIBERTY STORE | L4: CONNECTED STORE
C6: F&B | D6: N-F&B | E6: TOTAL | H6: F&B | I6: N-F&B | J6: TOTAL | M6: F&B | N6: N-F&B | O6: TOTAL
B7: MIX | C7: 0.7 | D7: 0.3 | E7: =SUM(C7:D7) -> 1 | G7: MIX | H7: 1 | I7: 0 | J7: =SUM(H7:I7) -> 1 | L7: MIX | M7: 0.9 | N7: 0.1 | O7: =SUM(M7:N7) -> 1
B8: MARGE | C8: 2.6 | D8: 1.45 | E8: 2.025 | G8: MARGE | H8: 2.6 | I8: - | J8: 2.6 | L8: MARGE | M8: 2.6 | N8: 1.8 | O8: 2.2
B9: IBB NICE | E9: =SUMPRODUCT(C8:D8,C7:D7)/SUM(C7:D7) -> 2.255 | G9: MER BOUL | J9: =SUMPRODUCT(H8:I8,H7:I7)/SUM(H7:I7) -> 2.6 | L9: MER MONT | O9: =SUMPRODUCT(M8:N8,M7:N7)/SUM(M7:N7) -> 2.52
G11: MIX | H11: 0.3 | I11: 0.7 | J11: =SUM(H11:I11) -> 1
G12: MARGE | H12: 2.6 | I12: 2 | J12: 2.3
G13: NOV MEG | J13: =SUMPRODUCT(H12:I12,H11:I11)/SUM(H11:I11) -> 2.18
G15: MIX | H15: =AVERAGE(H7,H11) -> 0.65 | I15: =AVERAGE(I7,I11) -> 0.35 | J15: =SUM(H15:I15) -> 1
G16: MARGE | H16: =AVERAGE(H8,H12) -> 2.6 | I16: =AVERAGE(I8,I12) -> 2 | J16: =AVERAGE(H16:I16) -> 2.3
B18: MOYENNE | E18: =SUMPRODUCT(C8:D8,C7:D7)/SUM(C7:D7) -> 2.255 | G18: MOYENNE | J18: =SUMPRODUCT(H16:I16,H15:I15)/SUM(H15:I15) -> 2.39 | L18: MOYENNE | O18: =SUMPRODUCT(M8:N8,M7:N7)/SUM(M7:N7) -> 2.52

Sheet REVENUS - IMPACT TO
B2: REVENUS ► TAUX D'OCCUPATION
B4: SIMPLY STORE | K4: LIBERTY STORE | T4: CONNECTED STORE
D6: CA HT | G6: CA TTC | M6: CA HT | P6: CA TTC | V6: CA HT | Y6: CA TTC
C7: TO MOYEN | D7: F&B | E7: N-F&B | F7: TOTAL | G7: F&B | H7: N-F&B | I7: TOTAL | L7: TO MOYEN | M7: F&B | N7: N-F&B | O7: TOTAL | P7: F&B | Q7: N-F&B | R7: TOTAL | U7: TO MOYEN | V7: F&B | W7: N-F&B | X7: TOTAL | Y7: F&B | Z7: N-F&B | AA7: TOTAL
B8: IBB NICE | C8: 0.78 | D8: 533.25 | E8: 187 | F8: =SUM(D8:E8) -> 720.25 | G8: 587.08333 | H8: 224.41667 | I8: =SUM(G8:H8) -> 811.5 | K8: MER BOUL | L8: 0.68 | M8: 1718.6667 | N8: 0 | O8: 1718.6548 | P8: 1910.4167 | Q8: 0 | R8: 1910.4167 | T8: MER MONT | U8: 0.75 | V8: 3503.3175 | W8: 130.64771 | X8: 3633.9652 | Y8: 3696 | Z8: 137.83333 | AA8: 3833.8333
K9: NOV MEG | L9: 0.67 | M9: 391.70854 | N9: 848.18803 | O9: 1239.8966 | P9: 437.64167 | Q9: 1015.225 | R9: 1452.8667
K10: MOYENNE | L10: =AVERAGE(L8:L9) -> 0.675 | M10: 1055.1876 | N10: 424.09402 | O10: 1479.2816 | P10: 1174.0292 | Q10: 507.6125 | R10: 1681.6417
B12: IMPACT | C12: 0.01 | D12: =($C$12*D8)/$C$8 -> 6.8365385 | E12: =($C$12*E8)/$C$8 -> 2.3974359 | F12: =($C$12*F8)/$C$8 -> 9.2339744 | G12: =($C$12*G8)/$C$8 -> 7.5267094 | H12: =($C$12*H8)/$C$8 -> 2.8771368 | I12: =($C$12*I8)/$C$8 -> 10.403846 | K12: IMPACT | L12: 0.01 | M12: =($L$12*M10)/$L$10 -> 15.632409 | N12: =($L$12*N10)/$L$10 -> 6.2828743 | O12: =($L$12*O10)/$L$10 -> 21.915283 | P12: =($L$12*P10)/$L$10 -> 17.393025 | Q12: =($L$12*Q10)/$L$10 -> 7.5201852 | R12: =($L$12*R10)/$L$10 -> 24.91321 | T12: IMPACT | U12: 0.01 | V12: =($U$12*V8)/$U$8 -> 46.7109 | W12: =($U$12*W8)/$U$8 -> 1.7419695 | X12: =($U$12*X8)/$U$8 -> 48.45287 | Y12: =($U$12*Y8)/$U$8 -> 49.28 | Z12: =($U$12*Z8)/$U$8 -> 1.8377778 | AA12: =($U$12*AA8)/$U$8 -> 51.117778
